Workbook

Sheet ⚙️ Assumptions
A1: ASSUMPTIONS & DRIVERS / GIẢ ĐỊNH & THÔNG SỐ ĐẦU VÀO
A5: Driver | B5: Value
A6: Start Month (Tháng bắt đầu) | B6: 46661
A7: Rent Area (Vị trí thuê địa điểm) | B7: Nearby Area(Cửa Nam, Nguyễn Hữu Huân, Triệu Việt Vương)
A8: Area (diện tích thuê) m2 | B8: 50
A9: Rent per m2 (Giá trên m2) | B9: =_xlfn.XLOOKUP(B7,'⚙️ Other Assumptions'!A8:A10,'⚙️ Other Assumptions'!B8:B10,1) -> 1150000
A10: Rent Price (Giá thuê) | B10: =B8*B9 -> 57500000
A11: Deposit month’s rent (Số tháng tiền cọc) | B11: 6
A12: Expected number of order sold per day (Công suất mục tiêu) | B12: 150
A13: Revenue Ramp-up Scenario (Kịch bản tăng trưởng doanh thu) | B13: Ramp-up Neutral
A14: Working Capital Buffer | B14: =_xlfn.LET( _xlpm.buffer_1,-SUM(OFFSET('💵 Cash Flow'!$C$11,0,0,1,_xlfn.XLOOKUP(1,SIGN('💵 Cash Flow'!$C$11:$BJ$11),'💵 Cash Flow'!$C$3:$BJ$3,"No Negative",0,1)-1)), _xlpm.Principal_buffer,-SUM(OFFSET('💵 Cash Flow'!$C$19,0,0,1,_xlfn.XLOOKUP(1,SIGN('💵 Cash Flow'!$C$11:$BJ$11),'💵 Cash Flow'!$C$3:$BJ$3,"No Negative",0,1)-1)), _xlpm.interest_buffer,-SUM(OFFSET('💵 Cash Flow'!$C$20,0,0,1,_xlfn.XLOOKUP(1,SIGN('💵 Cash Flow'!$C$11:$BJ$11),'💵 Cash Flow'!$C$3:$BJ$3,"No Negative",0,1)-1)), _xlpm.buffer_1 + _xlpm.Principal_buffer + _xlpm.interest_buffer) -> 2.6697327e+08
A16: Capital Expenditure (Chi phí đầu tư cố định) | B16: 300000000
A17: Deposit month’s rent $ (Cọc tiền thuê nhà) | B17: =$B$11*$B$10 -> 345000000
A18: Total | B18: =SUM(B16:B17) -> 645000000
A20: Capital Expenditure Breakdown (chi tiết Capex) | B20: % | C20: Qty | D20: Price
A21: Interior + concept design (Thiết kễ + nội thật quán) | B21: 0.23 | C21: 1 | D21: =$B$16*B21 -> 69000000
A22: Stove (Bếp điện) | B22: 0.17 | C22: 1 | D22: =$B$16*B22 -> 51000000
A23: Freezer (Tủ đông) | B23: 0.1 | C23: 1 | D23: =$B$16*B23 -> 30000000
A24: Refregerator (Tủ mát) | B24: 0.06 | C24: 1 | D24: =$B$16*B24 -> 18000000
A25: Shelf (Kệ inox đựng gia vị) | B25: 0.03 | C25: 1 | D25: =$B$16*B25 -> 9000000
A26: Others (Knives, cutting boards, pans) | B26: 0.04 | C26: 1 | D26: =$B$16*B26 -> 12000000
A27: SilverWare (Bát đũa, lọ gia vị) | B27: 0.05 | C27: 1 | D27: =$B$16*B27 -> 15000000
A28: Điều hòa ( 2 cái 1 chiều 9-12k BTU) | B28: 0.12 | C28: 2 | D28: =$B$16*B28 -> 36000000
A29: Electric (hệ thống điện 3 pha) | B29: 0.1 | C29: 1 | D29: =$B$16*B29 -> 30000000
A30: Water Line (Hệ thống nước + bể tách mỡ) | B30: 0.1 | C30: 1 | D30: =$B$16*B30 -> 30000000
A31: Total | B31: =SUM(B21:B30) -> 1 | D31: =SUM(D21:D30) -> 300000000
B37: First Year (Năm đầu tiên) | C37: Second Year (Năm thứ 2) | D37: Third Year (Năm thứ 3) | E37: Fourth Year (Năm thứ 4) | F37: Fifth Year (Năm thứ 5 )
B38: =YEAR(B6) -> 2027 | C38: =B38+1 -> 2028 | D38: =C38+1 -> 2029 | E38: =D38+1 -> 2030 | F38: =E38+1 -> 2031
A39: Raw Material % of Rev (tỷ trọng NVL/ Doanh thu) | B39: 0.35 | C39: 0.33 | D39: 0.3 | E39: 0.29 | F39: 0.29
A40: Electric Costs % of Rev (tỷ trọng chi phí điện/ Doanh thu) | B40: 0.04 | C40: 0.04 | D40: 0.04 | E40: 0.04 | F40: 0.04
A41: Water Cost % of Rev (tỷ trọng tiền nước/ Doanh thu) | B41: 0.015 | C41: 0.015 | D41: 0.015 | E41: 0.015 | F41: 0.015
A42: Maintainace Cost of Rev (Chi phí bảo trì bảo dưỡng) | B42: 0.01 | C42: 0.01 | D42: 0.03 | E42: 0.03 | F42: 0.04

Sheet 📋 Cover
A1: F&B RESTAURANT FP&A MODEL TEMPLATE
A4: Driver-Based Planning | Bilingual EN / VI | 36-Month Horizon
B6: PROJECT INFORMATION / THÔNG TIN DỰ ÁN
B7: Project Name / Tên dự án | C7: [Enter project name]
B8: Location / Địa điểm | C8: [Enter address]
B9: Concept / Mô hình | C9: [e.g. Casual Dining / Fine Dining / Fast Casual]
B10: Model Owner / Người lập | C10: [Name]
B11: Version / Phiên bản | C11: v1.0
B12: Date / Ngày | C12: [Date]
B13: Base Currency / Tiền tệ | C13: VNĐ
B14: Forecast Period | C14: 36 months / 3 years
B16: SHEET INDEX / DANH MỤC TRANG TÍNH | D16: PURPOSE / MỤC ĐÍCH
B17: 📋 Cover | C17: Project info, instructions, color legend
B18: ⚙️ Assumptions | C18: All input drivers – edit ONLY here / Tất cả giả định đầu vào
B19: 💰 Revenue | C19: Driver-based revenue forecast / Dự báo doanh thu
B20: 📦 COGS & OpEx | C20: Cost of goods + operating cost drivers / Chi phí biến đổi & cố định
B21: 👥 HR Plan | C21: Headcount plan & payroll budget / Kế hoạch nhân sự & lương
B22: 🏦 Loan Schedule | C22: Debt drawdown & amortisation / Lịch vay & trả nợ
B23: 📊 P&L Detail | C23: Monthly detailed P&L / Báo cáo KQHĐKD chi tiết
B24: 💵 Cash Flow | C24: Full 3-statement cash flow / Dòng tiền đầy đủ
B25: 🔄 Rolling Forecast | C25: 12-month rolling forecast vs actuals / Dự báo cuốn chiếu
B26: 🎯 Scenario Manager | C26: Bear / Base / Bull scenarios / Các kịch bản
B28: COLOR LEGEND / CHÚ THÍCH MÀU SẮC
B29: Blue text on yellow → Hardcoded INPUT – change these / Ô nhập liệu
B30: Green text → Formula pulling from another sheet / Liên kết sheet khác
B31: Black text → Formula / calculated cell / Công thức tính toán
B32: Red text → External link / Liên kết file ngoài
B33: Green background → Subtotal / sub-total row / Dòng tổng phụ
B34: Light green background → Alternating row / Hàng xen kẽ
B36: ⚠️ IMPORTANT / LƯU Ý: Only edit cells with BLUE text on YELLOW background in the Assumptions sheet. All other sheets are formula-driven and update automatically. / Chỉ chỉnh sửa các ô có chữ xanh dương nền vàng trong trang Assumptions. Tất cả trang còn lại được tính tự động.

Sheet ⚙️ Assumptions_1
A1: ASSUMPTIONS & DRIVERS / GIẢ ĐỊNH & THÔNG SỐ ĐẦU VÀO
A3: DRIVER / THÔNG SỐ | B3: VALUE / GIÁ TRỊ | C3: UNIT / ĐƠN VỊ | D3: YoY / TREND | E3: NOTES / GHI CHÚ
A4: A. VENUE & CAPACITY / MẶT BẰNG & CÔNG SUẤT
A5: Floor area / Diện tích sàn (m²) | C5: m² | E5: Total leased area
A6: Seating capacity / Số chỗ ngồi | C6: seats/chỗ | E6: Indoor + terrace
A7: Operating days/month / Ngày hoạt động TB | B7: 30 | C7: days/ngày | D7: —
A8: Floors / Tầng | E8: Floor number in building
A9: Opening month / Tháng khai trương | B9: M01 | E9: Enter M01–M36
A10: B. REVENUE DRIVERS / THÔNG SỐ DOANH THU
A11: Avg spend per cover – Yr1 / Giá xuất Năm 1 | C11: VNĐ | E11: Average revenue per diner
A12: Price increase YoY / Tăng giá mỗi năm | C12: %/year | D12: YoY | E12: Applied annually from Year 2
A13: Table turns (normal) / Vòng quay bàn TB | C13: turns/day | E13: e.g. 2.5
A14: Table turns (peak season) / Vòng quay cao điểm | C14: turns/day | E14: Tet, Christmas
A15: Target covers/day – Steady State / Lượng khách SS | C15: covers/khách | E15: Reference market analysis
A16: Ramp M01 / Tháng 1 (% SS) | B16: 0.05 | C16: % | D16: Ramp | E16: Opening month
A17: Ramp M02 (% SS) | B17: 0.1 | C17: % | D17: Ramp
A18: Ramp M03 (% SS) | B18: 0.2 | C18: % | D18: Ramp
A19: Ramp M04 (% SS) | B19: 0.35 | C19: % | D19: Ramp
A20: Ramp M05 (% SS) | B20: 0.5 | C20: % | D20: Ramp
A21: Ramp M06 (% SS) | B21: 0.7 | C21: % | D21: Ramp
A22: Steady state from / Đạt tốc độ bình thường từ | B22: M07 | D22: — | E22: Enter month code e.g. M07
A23: Seasonal peak multiplier / Hệ số mùa cao điểm | B23: 1.2 | C23: x | D23: — | E23: Applied to Tet/Christmas months
A24: Seasonal trough multiplier / Hệ số mùa thấp điểm | B24: 0.85 | C24: x | D24: — | E24: Applied to slow months (e.g. post-Tet)
A25: C. FOOD & BEVERAGE COST / CHI PHÍ THỰC PHẨM & ĐỒ UỐNG
A26: Food cost % revenue – Yr1 / Định mức TP Năm 1 | B26: 0.3 | C26: % rev | D26: YoY | E26: Typically 28–35% for F&B
A27: Beverage cost % revenue – Yr1 / Định mức đồ uống | B27: 0.2 | C27: % rev | D27: — | E27: Typically 18–25% for beverages
A28: Input price inflation YoY / Tăng giá nguyên liệu | B28: 0.1 | C28: %/year | D28: YoY | E28: Apply to COGS % from Year 2
A29: Food revenue mix / Tỷ lệ doanh thu thức ăn | B29: 0.65 | C29: % total rev | D29: — | E29: Remaining = beverage
A30: D. FIXED OPERATING COSTS / CHI PHÍ CỐ ĐỊNH VẬN HÀNH
A31: Base rent / Thuê mặt bằng (VNĐ/m²/month) | C31: VNĐ/m²/tháng | D31: — | E31: Monthly rent per m²
A32: FX rate / Tỷ giá (VNĐ/USD) | B32: 24000 | C32: VNĐ/USD | D32: — | E32: Update if rent quoted in USD
A33: Utilities / Điện nước (VNĐ/month) | C33: VNĐ/tháng | D33: YoY | E33: Electricity, water, gas
A34: Repairs & maintenance / Sửa chữa bảo trì | C34: VNĐ/tháng | D34: YoY
A35: Insurance / Bảo hiểm tài sản | C35: VNĐ/tháng | D35: —
A36: Fixed cost growth YoY / Tăng CP cố định | B36: 0.1 | C36: %/year | D36: YoY | E36: Applied from Year 2
A37: E. MARKETING & PROMOTIONS / MARKETING & KHUYẾN MẠI
A38: Monthly marketing budget / Ngân sách marketing/tháng | C38: VNĐ/tháng | D38: —
A39: Grand opening budget / Ngân sách khai trương | C39: VNĐ | D39: One-off
A40: Loyalty discount % / Giảm giá thành viên thân thiết | B40: 0.15 | C40: % | D40: — | E40: % discount on qualifying visits
A41: Loyalty member % of covers / % KH thành viên | B41: 0.05 | C41: % covers | D41: — | E41: % of covers receiving loyalty discount
...

Sheet 💰 Revenue
A1: REVENUE FORECAST / DỰ BÁO DOANH THU
D2: 1 | E2: 2 | F2: 3 | G2: 4 | H2: 5 | I2: 6 | J2: 7 | K2: 8 | L2: 9 | M2: 10 | N2: 11 | O2: 12 | P2: 13 | Q2: 14 | R2: 15 | S2: 16 | T2: 17 | U2: 18 | V2: 19 | W2: 20 | X2: 21 | Y2: 22 | Z2: 23 | AA2: 24 | AB2: 25 | AC2: 26 | AD2: 27 | AE2: 28 | AF2: 29 | AG2: 30 | AH2: 31 | AI2: 32 | AJ2: 33 | AK2: 34 | AL2: 35 | AM2: 36 | AN2: 37 | AO2: 38 | AP2: 39 | AQ2: 40 | AR2: 41 | AS2: 42 | AT2: 43 | AU2: 44 | AV2: 45 | AW2: 46 | AX2: 47 | AY2: 48 | AZ2: 49 | BA2: 50 | BB2: 51 | BC2: 52 | BD2: 53 | BE2: 54 | BF2: 55 | BG2: 56 | BH2: 57 | BI2: 58 | BJ2: 59
C3: =YEAR(C5)-YEAR('⚙️ Assumptions'!$B$6) + 1 -> 1 | D3: =YEAR(D5)-YEAR('⚙️ Assumptions'!$B$6) + 1 -> 1 | E3: =YEAR(E5)-YEAR('⚙️ Assumptions'!$B$6) + 1 -> 1 | F3: =YEAR(F5)-YEAR('⚙️ Assumptions'!$B$6) + 1 -> 2 | G3: =YEAR(G5)-YEAR('⚙️ Assumptions'!$B$6) + 1 -> 2 | H3: =YEAR(H5)-YEAR('⚙️ Assumptions'!$B$6) + 1 -> 2 | I3: =YEAR(I5)-YEAR('⚙️ Assumptions'!$B$6) + 1 -> 2 | J3: =YEAR(J5)-YEAR('⚙️ Assumptions'!$B$6) + 1 -> 2 | ... BJ3: =YEAR(BJ5)-YEAR('⚙️ Assumptions'!$B$6) + 1 -> 6
C4: 1 | D4: 2 | E4: 3 | F4: 4 | G4: 5 | H4: 6 | I4: 7 | J4: 8 | K4: 9 | L4: 10 | M4: 11 | N4: 12 | O4: 13 | P4: 14 | Q4: 15 | R4: 16 | S4: 17 | T4: 18 | U4: 19 | V4: 20 | W4: 21 | X4: 22 | Y4: 23 | Z4: 24 | AA4: 25 | AB4: 26 | AC4: 27 | AD4: 28 | AE4: 29 | AF4: 30 | AG4: 31 | AH4: 32 | AI4: 33 | AJ4: 34 | AK4: 35 | AL4: 36 | AM4: 37 | AN4: 38 | AO4: 39 | AP4: 40 | AQ4: 41 | AR4: 42 | AS4: 43 | AT4: 44 | AU4: 45 | AV4: 46 | AW4: 47 | AX4: 48 | AY4: 49 | AZ4: 50 | BA4: 51 | BB4: 52 | BC4: 53 | BD4: 54 | BE4: 55 | BF4: 56 | BG4: 57 | BH4: 58 | BI4: 59 | BJ4: 60
A5: LINE ITEM / CHỈ TIÊU | B5: 3-YEAR TOTAL / TỔNG 3 NĂM | C5: ='⚙️ Assumptions'!B6 -> 46661 | D5: =EDATE(C$5,$D$2) -> 46692 | E5: =EDATE($C$5,E2) -> 46722 | F5: =EDATE($C$5,F2) -> 46753 | G5: =EDATE($C$5,G2) -> 46784 | H5: =EDATE($C$5,H2) -> 46813 | I5: =EDATE($C$5,I2) -> 46844 | J5: =EDATE($C$5,J2) -> 46874 | K5: =EDATE($C$5,K2) -> 46905 | L5: =EDATE($C$5,L2) -> 46935 | ... BJ5: =EDATE($C$5,BJ2) -> 48458
A6: A. REVENUE DRIVERS / THÔNG SỐ DOANH THU
A7: Covers/day exclude seasonal index / Khách/ngày | B7: =AVERAGEA(C7:AL7) -> 144.16667 | C7: =_xlfn.LET( _xlpm.Ramp_up_Percentage, INDEX('⚙️ Other Assumptions'!$B$17:$Q$19,MATCH('⚙️ Assumptions'!$B$13,'⚙️ Other Assumptions'!$A$17:$A$19,0),MATCH(C4,'⚙️ Other Assumptions'!$B$14:$AI$14,0)), _xlpm.Default_max_val,INDEX('⚙️ Other Assumptions'!$B$24:$B$26,MATCH('⚙️ Assumptions'!$B$13,'⚙️ Other Assumptions'!$A$24:$A$26)), _xlpm.Expected_number_of_sales, '⚙️ Assumptions'!$B$12, IFERROR(_xlpm.Ramp_up_Percentage,_xlpm.Default_max_val)*_xlpm.Expected_number_of_sales) -> 0 | D7: =_xlfn.LET( _xlpm.Ramp_up_Percentage, INDEX('⚙️ Other Assumptions'!$B$17:$Q$19,MATCH('⚙️ Assumptions'!$B$13,'⚙️ Other Assumptions'!$A$17:$A$19,0),MATCH(D4,'⚙️ Other Assumptions'!$B$14:$AI$14,0)), _xlpm.Default_max_val,INDEX('⚙️ Other Assumptions'!$B$24:$B$26,MATCH('⚙️ Assumptions'!$B$13,'⚙️ Other Assumptions'!$A$24:$A$26)), _xlpm.Expected_number_of_sales, '⚙️ Assumptions'!$B$12, IFERROR(_xlpm.Ramp_up_Percentage,_xlpm.Default_max_val)*_xlpm.Expected_number_of_sales) -> 0 | E7: =_xlfn.LET( _xlpm.Ramp_up_Percentage, INDEX('⚙️ Other Assumptions'!$B$17:$Q$19,MATCH('⚙️ Assumptions'!$B$13,'⚙️ Other Assumptions'!$A$17:$A$19,0),MATCH(E4,'⚙️ Other Assumptions'!$B$14:$AI$14,0)), _xlpm.Default_max_val,INDEX('⚙️ Other Assumptions'!$B$24:$B$26,MATCH('⚙️ Assumptions'!$B$13,'⚙️ Other Assumptions'!$A$24:$A$26)), _xlpm.Expected_number_of_sales, '⚙️ Assumptions'!$B$12, IFERROR(_xlpm.Ramp_up_Percentage,_xlpm.Default_max_val)*_xlpm.Expected_number_of_sales) -> 45 | F7: =_xlfn.LET( _xlpm.Ramp_up_Percentage, INDEX('⚙️ Other Assumptions'!$B$17:$Q$19,MATCH('⚙️ Assumptions'!$B$13,'⚙️ Other Assumptions'!$A$17:$A$19,0),MATCH(F4,'⚙️ Other Assumptions'!$B$14:$AI$14,0)), _xlpm.Default_max_val,INDEX('⚙️ Other Assumptions'!$B$24:$B$26,MATCH('⚙️ Assumptions'!$B$13,'⚙️ Other Assumptions'!$A$24:$A$26)), _xlpm.Expected_number_of_sales, '⚙️ Assumptions'!$B$12, IFERROR(_xlpm.Ramp_up_Percentage,_xlpm.Default_max_val)*_xlpm.Expected_number_of_sales) -> 45 | G7: =_xlfn.LET( _xlpm.Ramp_up_Percentage, INDEX('⚙️ Other Assumptions'!$B$17:$Q$19,MATCH('⚙️ Assumptions'!$B$13,'⚙️ Other Assumptions'!$A$17:$A$19,0),MATCH(G4,'⚙️ Other Assumptions'!$B$14:$AI$14,0)), _xlpm.Default_max_val,INDEX('⚙️ Other Assumptions'!$B$24:$B$26,MATCH('⚙️ Assumptions'!$B$13,'⚙️ Other Assumptions'!$A$24:$A$26)), _xlpm.Expected_number_of_sales, '⚙️ Assumptions'!$B$12, IFERROR(_xlpm.Ramp_up_Percentage,_xlpm.Default_max_val)*_xlpm.Expected_number_of_sales) -> 75 | H7: =_xlfn.LET( _xlpm.Ramp_up_Percentage, INDEX('⚙️ Other Assumptions'!$B$17:$Q$19,MATCH('⚙️ Assumptions'!$B$13,'⚙️ Other Assumptions'!$A$17:$A$19,0),MATCH(H4,'⚙️ Other Assumptions'!$B$14:$AI$14,0)), _xlpm.Default_max_val,INDEX('⚙️ Other Assumptions'!$B$24:$B$26,MATCH('⚙️ Assumptions'!$B$13,'⚙️ Other Assumptions'!$A$24:$A$26)), _xlpm.Expected_number_of_sales, '⚙️ Assumptions'!$B$12, IFERROR(_xlpm.Ramp_up_Percentage,_xlpm.Default_max_val)*_xlpm.Expected_number_of_sales) -> 75 | I7: =_xlfn.LET( _xlpm.Ramp_up_Percentage, INDEX('⚙️ Other Assumptions'!$B$17:$Q$19,MATCH('⚙️ Assumptions'!$B$13,'⚙️ Other Assumptions'!$A$17:$A$19,0),MATCH(I4,'⚙️ Other Assumptions'!$B$14:$AI$14,0)), _xlpm.Default_max_val,INDEX('⚙️ Other Assumptions'!$B$24:$B$26,MATCH('⚙️ Assumptions'!$B$13,'⚙️ Other Assumptions'!$A$24:$A$26)), _xlpm.Expected_number_of_sales, '⚙️ Assumptions'!$B$12, IFERROR(_xlpm.Ramp_up_Percentage,_xlpm.Default_max_val)*_xlpm.Expected_number_of_sales) -> 112.5 | J7: =_xlfn.LET( _xlpm.Ramp_up_Percentage, INDEX('⚙️ Other Assumptions'!$B$17:$Q$19,MATCH('⚙️ Assumptions'!$B$13,'⚙️ Other Assumptions'!$A$17:$A$19,0),MATCH(J4,'⚙️ Other Assumptions'!$B$14:$AI$14,0)), _xlpm.Default_max_val,INDEX('⚙️ Other Assumptions'!$B$24:$B$26,MATCH('⚙️ Assumptions'!$B$13,'⚙️ Other Assumptions'!$A$24:$A$26)), _xlpm.Expected_number_of_sales, '⚙️ Assumptions'!$B$12, IFERROR(_xlpm.Ramp_up_Percentage,_xlpm.Default_max_val)*_xlpm.Expected_number_of_sales) -> 112.5 | ... BJ7: =_xlfn.LET( _xlpm.Ramp_up_Percentage, INDEX('⚙️ Other Assumptions'!$B$17:$Q$19,MATCH('⚙️ Assumptions'!$B$13,'⚙️ Other Assumptions'!$A$17:$A$19,0),MATCH(BJ4,'⚙️ Other Assumptions'!$B$14:$AI$14,0)), _xlpm.Default_max_val,INDEX('⚙️ Other Assumptions'!$B$24:$B$26,MATCH('⚙️ Assumptions'!$B$13,'⚙️ Other Assumptions'!$A$24:$A$26)), _xlpm.Expected_number_of_sales, '⚙️ Assumptions'!$B$12, IFERROR(_xlpm.Ramp_up_Percentage,_xlpm.Default_max_val)*_xlpm.Expected_number_of_sales) -> 180
A8: Operating days / Ngày hoạt động | B8: =AVERAGEA(C8:AL8) -> 30.444444 | C8: =DAY(DATE(YEAR(C5), MONTH(C5)+1, 0)) -> 31 | D8: =DAY(DATE(YEAR(D5), MONTH(D5)+1, 0)) -> 30 | E8: =DAY(DATE(YEAR(E5), MONTH(E5)+1, 0)) -> 31 | F8: =DAY(DATE(YEAR(F5), MONTH(F5)+1, 0)) -> 31 | G8: =DAY(DATE(YEAR(G5), MONTH(G5)+1, 0)) -> 29 | H8: =DAY(DATE(YEAR(H5), MONTH(H5)+1, 0)) -> 31 | I8: =DAY(DATE(YEAR(I5), MONTH(I5)+1, 0)) -> 30 | J8: =DAY(DATE(YEAR(J5), MONTH(J5)+1, 0)) -> 31 | ... BJ8: =DAY(DATE(YEAR(BJ5), MONTH(BJ5)+1, 0)) -> 30
A9: Seasonal index / Hệ số mùa vụ | B9: =SUM(C9:AL9) -> 38.1 | C9: =INDEX('⚙️ Other Assumptions'!$B$16:$M$16,MATCH(MONTH(C5),'⚙️ Other Assumptions'!$B$14:$M$14,0)) -> 0.95 | D9: =INDEX('⚙️ Other Assumptions'!$B$16:$M$16,MATCH(MONTH(D5),'⚙️ Other Assumptions'!$B$14:$M$14,0)) -> 1.05 | E9: =INDEX('⚙️ Other Assumptions'!$B$16:$M$16,MATCH(MONTH(E5),'⚙️ Other Assumptions'!$B$14:$M$14,0)) -> 1.2 | F9: =INDEX('⚙️ Other Assumptions'!$B$16:$M$16,MATCH(MONTH(F5),'⚙️ Other Assumptions'!$B$14:$M$14,0)) -> 1.2 | G9: =INDEX('⚙️ Other Assumptions'!$B$16:$M$16,MATCH(MONTH(G5),'⚙️ Other Assumptions'!$B$14:$M$14,0)) -> 0.85 | H9: =INDEX('⚙️ Other Assumptions'!$B$16:$M$16,MATCH(MONTH(H5),'⚙️ Other Assumptions'!$B$14:$M$14,0)) -> 0.95 | I9: =INDEX('⚙️ Other Assumptions'!$B$16:$M$16,MATCH(MONTH(I5),'⚙️ Other Assumptions'!$B$14:$M$14,0)) -> 1.15 | J9: =INDEX('⚙️ Other Assumptions'!$B$16:$M$16,MATCH(MONTH(J5),'⚙️ Other Assumptions'!$B$14:$M$14,0)) -> 1.05 | ... BJ9: =INDEX('⚙️ Other Assumptions'!$B$16:$M$16,MATCH(MONTH(BJ5),'⚙️ Other Assumptions'!$B$14:$M$14,0)) -> 0.95
A10: Avg spend/cover / Giá 1 xuất (VNĐ) | B10: =AVERAGEA(C10:AL10) -> 75000 | C10: 75000 | D10: 75000 | E10: 75000 | F10: 75000 | G10: 75000 | H10: 75000 | I10: 75000 | J10: 75000 | K10: 75000 | L10: 75000 | M10: 75000 | N10: 75000 | O10: 75000 | P10: 75000 | Q10: 75000 | R10: 75000 | S10: 75000 | T10: 75000 | U10: 75000 | V10: 75000 | W10: 75000 | X10: 75000 | Y10: 75000 | Z10: 75000 | AA10: 75000 | AB10: 75000 | AC10: 75000 | AD10: 75000 | AE10: 75000 | AF10: 75000 | AG10: 75000 | AH10: 75000 | AI10: 75000 | AJ10: 75000 | AK10: 75000 | AL10: 75000 | AM10: 75000 | AN10: 75000 | AO10: 75000 | AP10: 75000 | AQ10: 75000 | AR10: 75000 | AS10: 75000 | AT10: 75000 | AU10: 75000 | AV10: 75000 | AW10: 75000 | AX10: 75000 | AY10: 75000 | AZ10: 75000 | BA10: 75000 | BB10: 75000 | BC10: 75000 | BD10: 75000 | BE10: 75000 | BF10: 75000 | BG10: 75000 | BH10: 75000 | BI10: 75000 | BJ10: 75000
A11: Food revenue mix / Tỷ lệ DT thức ăn | B11: =AVERAGE(C11:AL11) -> 0.8 | C11: 0.8 | D11: 0.8 | E11: 0.8 | F11: 0.8 | G11: 0.8 | H11: 0.8 | I11: 0.8 | J11: 0.8 | K11: 0.8 | L11: 0.8 | M11: 0.8 | N11: 0.8 | O11: 0.8 | P11: 0.8 | Q11: 0.8 | R11: 0.8 | S11: 0.8 | T11: 0.8 | U11: 0.8 | V11: 0.8 | W11: 0.8 | X11: 0.8 | Y11: 0.8 | Z11: 0.8 | AA11: 0.8 | AB11: 0.8 | AC11: 0.8 | AD11: 0.8 | AE11: 0.8 | AF11: 0.8 | AG11: 0.8 | AH11: 0.8 | AI11: 0.8 | AJ11: 0.8 | AK11: 0.8 | AL11: 0.8 | AM11: 0.8 | AN11: 0.8 | AO11: 0.8 | AP11: 0.8 | AQ11: 0.8 | AR11: 0.8 | AS11: 0.8 | AT11: 0.8 | AU11: 0.8 | AV11: 0.8 | AW11: 0.8 | AX11: 0.8 | AY11: 0.8 | AZ11: 0.8 | BA11: 0.8 | BB11: 0.8 | BC11: 0.8 | BD11: 0.8 | BE11: 0.8 | BF11: 0.8 | BG11: 0.8 | BH11: 0.8 | BI11: 0.8 | BJ11: 0.8
A12: B. REVENUE CALCULATION / TÍNH DOANH THU
A13: Total covers / Tổng số suất ăn | B13: =AVERAGEA(C13:AL13) -> 4647.0625 | C13: =C7*C8*C9 -> 0 | D13: =D7*D8*D9 -> 0 | E13: =E7*E8*E9 -> 1674 | F13: =F7*F8*F9 -> 1674 | G13: =G7*G8*G9 -> 1848.75 | H13: =H7*H8*H9 -> 2208.75 | I13: =I7*I8*I9 -> 3881.25 | J13: =J7*J8*J9 -> 3661.875 | ... BJ13: =BJ7*BJ8*BJ9 -> 5130
A14: Gross Revenue / Doanh thu gộp (VNĐ) | B14: =SUM(C14:AL14) -> 12547068750 | C14: =_xlfn.LET( _xlpm.number_of_serves, C13, _xlpm.avg_spend, C10, _xlpm.avg_days_per_month,C8, _xlpm.number_of_serves*_xlpm.avg_spend) -> 0 | D14: =_xlfn.LET( _xlpm.number_of_serves, D13, _xlpm.avg_spend, D10, _xlpm.avg_days_per_month,D8, _xlpm.number_of_serves*_xlpm.avg_spend) -> 0 | E14: =_xlfn.LET( _xlpm.number_of_serves, E13, _xlpm.avg_spend, E10, _xlpm.avg_days_per_month,E8, _xlpm.number_of_serves*_xlpm.avg_spend) -> 125550000 | F14: =_xlfn.LET( _xlpm.number_of_serves, F13, _xlpm.avg_spend, F10, _xlpm.avg_days_per_month,F8, _xlpm.number_of_serves*_xlpm.avg_spend) -> 125550000 | G14: =_xlfn.LET( _xlpm.number_of_serves, G13, _xlpm.avg_spend, G10, _xlpm.avg_days_per_month,G8, _xlpm.number_of_serves*_xlpm.avg_spend) -> 138656250 | H14: =_xlfn.LET( _xlpm.number_of_serves, H13, _xlpm.avg_spend, H10, _xlpm.avg_days_per_month,H8, _xlpm.number_of_serves*_xlpm.avg_spend) -> 165656250 | I14: =_xlfn.LET( _xlpm.number_of_serves, I13, _xlpm.avg_spend, I10, _xlpm.avg_days_per_month,I8, _xlpm.number_of_serves*_xlpm.avg_spend) -> 291093750 | J14: =_xlfn.LET( _xlpm.number_of_serves, J13, _xlpm.avg_spend, J10, _xlpm.avg_days_per_month,J8, _xlpm.number_of_serves*_xlpm.avg_spend) -> 274640625 | ... BJ14: =_xlfn.LET( _xlpm.number_of_serves, BJ13, _xlpm.avg_spend, BJ10, _xlpm.avg_days_per_month,BJ8, _xlpm.number_of_serves*_xlpm.avg_spend) -> 384750000
A15: Food revenue / DT thức ăn (VNĐ) | B15: =SUM(C15:AL15) -> 10037655000 | C15: =C14*C11 -> 0 | D15: =D14*D11 -> 0 | E15: =E14*E11 -> 100440000 | F15: =F14*F11 -> 100440000 | G15: =G14*G11 -> 110925000 | H15: =H14*H11 -> 132525000 | I15: =I14*I11 -> 232875000 | J15: =J14*J11 -> 219712500 | ... BJ15: =BJ14*BJ11 -> 307800000
A16: Beverage revenue / DT đồ uống (VNĐ) | B16: =SUM(C16:AL16) -> 2509413750 | C16: =C14-C15 -> 0 | D16: =D14-D15 -> 0 | E16: =E14-E15 -> 25110000 | F16: =F14-F15 -> 25110000 | G16: =G14-G15 -> 27731250 | H16: =H14-H15 -> 33131250 | I16: =I14-I15 -> 58218750 | J16: =J14-J15 -> 54928125 | ... BJ16: =BJ14-BJ15 -> 76950000
A17: (-) Loyalty discount / Giảm giá thành viên (VNĐ) | B17: =SUM(C17:AL17) -> 0 | C17: =C14*0.15*0 -> 0 | D17: =D14*0.15*0 -> 0 | E17: =E14*0.15*0 -> 0 | F17: =F14*0.15*0 -> 0 | G17: =G14*0.15*0 -> 0 | H17: =H14*0.15*0 -> 0 | I17: =I14*0.15*0 -> 0 | J17: =J14*0.15*0 -> 0 | ... BJ17: =BJ14*0.15*0 -> 0
A18: (-) Promotion cost / Chi phí khuyến mại (VNĐ) | B18: =SUM(C18:AL18) -> 0
A19: NET REVENUE / DOANH THU THUẦN (VNĐ) | B19: =SUM(C19:AL19) -> 12547068750 | C19: =C14-C17-C18 -> 0 | D19: =D14-D17-D18 -> 0 | E19: =E14-E17-E18 -> 125550000 | F19: =F14-F17-F18 -> 125550000 | G19: =G14-G17-G18 -> 138656250 | H19: =H14-H17-H18 -> 165656250 | I19: =I14-I17-I18 -> 291093750 | J19: =J14-J17-J18 -> 274640625 | ... BJ19: =BJ14-BJ17-BJ18 -> 384750000
A20: C. ANNUAL SUMMARY / TÓM TẮT NĂM
A21: Year 1 Net Revenue / DT Thuần Năm 1 (VNĐ) | B21: =SUMIF($C$3:$BJ$3,1,$C$19:$BJ$19) -> 125550000
A22: Year 2 Net Revenue / DT Thuần Năm 2 (VNĐ) | B22: =SUMIF($C$3:$BJ$3,2,$C$19:$BJ$19) -> 3386643750
A23: Year 3 Net Revenue / DT Thuần Năm 3 (VNĐ) | B23: =SUMIF($C$3:$BJ$3,3,$C$19:$BJ$19) -> 5138100000
A24: Year 4 Net Revenue / DT Thuần Năm 4 (VNĐ) | B24: =SUMIF($C$3:$BJ$3,4,$C$19:$BJ$19) -> 5221800000
A25: Year 5 Net Revenue / DT Thuần Năm 5 (VNĐ) | B25: =SUMIF($C$3:$BJ$3,5,$C$19:$BJ$19) -> 5221800000
A26: D. PROJECT CLOSE-OUT / THU HỒI CUỐI DỰ ÁN
A27: Working capital recovery + Deposit + Liquidation (VNĐ) | B27: =SUM(C27:AL27) -> 0
A28: TOTAL REVENUE incl. close-out / TỔNG DT (VNĐ) | B28: =SUM(C28:AL28) -> 12547068750 | C28: =C19+C27 -> 0 | D28: =D19+D27 -> 0 | E28: =E19+E27 -> 125550000 | F28: =F19+F27 -> 125550000 | G28: =G19+G27 -> 138656250 | H28: =H19+H27 -> 165656250 | I28: =I19+I27 -> 291093750 | J28: =J19+J27 -> 274640625 | ... AL28: =AL19+AL27 -> 384750000

Sheet 📦 COGS & OpEx
A1: COGS & OPERATING COST FORECAST / CHI PHÍ HOẠT ĐỘNG
B2: TOTAL / TỔNG | C2: YEAR 1 / NĂM 1 | O2: YEAR 2 / NĂM 2 | AA2: YEAR 3 / NĂM 3
A3: LINE ITEM / CHỈ TIÊU | B3: 5-YEAR TOTAL / TỔNG 5 NĂM | C3: ='⚙️ Assumptions'!B6 -> 46661 | D3: =EDATE($C$3,'💰 Revenue'!D2) -> 46692 | E3: =EDATE($C$3,'💰 Revenue'!E2) -> 46722 | F3: =EDATE($C$3,'💰 Revenue'!F2) -> 46753 | G3: =EDATE($C$3,'💰 Revenue'!G2) -> 46784 | H3: =EDATE($C$3,'💰 Revenue'!H2) -> 46813 | I3: =EDATE($C$3,'💰 Revenue'!I2) -> 46844 | J3: =EDATE($C$3,'💰 Revenue'!J2) -> 46874 | K3: =EDATE($C$3,'💰 Revenue'!K2) -> 46905 | ... BJ3: =EDATE($C$3,'💰 Revenue'!BJ2) -> 48458
A4: A. COST OF GOODS SOLD / GIÁ VỐN HÀNG BÁN
A5: Raw Material % per Rev /Tỷ lệ NVL trên doanh thu | B5: =AVERAGEA(C5:AL5) -> 0.31166667 | C5: =_xlfn.IFNA(INDEX('⚙️ Assumptions'!$B$39:$F$39,MATCH(YEAR(C3),'⚙️ Assumptions'!$B$38:$F$38,0)),OFFSET(C5,,-1)) -> 0.35 | D5: =_xlfn.IFNA(INDEX('⚙️ Assumptions'!$B$39:$F$39,MATCH(YEAR(D3),'⚙️ Assumptions'!$B$38:$F$38,0)),OFFSET(D5,,-1)) -> 0.35 | E5: =_xlfn.IFNA(INDEX('⚙️ Assumptions'!$B$39:$F$39,MATCH(YEAR(E3),'⚙️ Assumptions'!$B$38:$F$38,0)),OFFSET(E5,,-1)) -> 0.35 | F5: =_xlfn.IFNA(INDEX('⚙️ Assumptions'!$B$39:$F$39,MATCH(YEAR(F3),'⚙️ Assumptions'!$B$38:$F$38,0)),OFFSET(F5,,-1)) -> 0.33 | G5: =_xlfn.IFNA(INDEX('⚙️ Assumptions'!$B$39:$F$39,MATCH(YEAR(G3),'⚙️ Assumptions'!$B$38:$F$38,0)),OFFSET(G5,,-1)) -> 0.33 | H5: =_xlfn.IFNA(INDEX('⚙️ Assumptions'!$B$39:$F$39,MATCH(YEAR(H3),'⚙️ Assumptions'!$B$38:$F$38,0)),OFFSET(H5,,-1)) -> 0.33 | I5: =_xlfn.IFNA(INDEX('⚙️ Assumptions'!$B$39:$F$39,MATCH(YEAR(I3),'⚙️ Assumptions'!$B$38:$F$38,0)),OFFSET(I5,,-1)) -> 0.33 | J5: =_xlfn.IFNA(INDEX('⚙️ Assumptions'!$B$39:$F$39,MATCH(YEAR(J3),'⚙️ Assumptions'!$B$38:$F$38,0)),OFFSET(J5,,-1)) -> 0.33 | ... BJ5: =_xlfn.IFNA(INDEX('⚙️ Assumptions'!$B$39:$F$39,MATCH(YEAR(BJ3),'⚙️ Assumptions'!$B$38:$F$38,0)),OFFSET(BJ5,,-1)) -> 0.29
A6: Raw Material / Giá vốn | B6: =SUM(C6:AL6) -> 3066423750 | C6: ='💰 Revenue'!C15*C5 -> 0 | D6: ='💰 Revenue'!D15*D5 -> 0 | E6: ='💰 Revenue'!E15*E5 -> 35154000 | F6: ='💰 Revenue'!F15*F5 -> 33145200 | G6: ='💰 Revenue'!G15*G5 -> 36605250 | H6: ='💰 Revenue'!H15*H5 -> 43733250 | I6: ='💰 Revenue'!I15*I5 -> 76848750 | J6: ='💰 Revenue'!J15*J5 -> 72505125 | ... BJ6: ='💰 Revenue'!BJ15*BJ5 -> 89262000
A7: TOTAL COGS / TỔNG GIÁ VỐN (VNĐ) | B7: =SUM(C7:AL7) -> 3066423750 | C7: =C6 -> 0 | D7: =D6 -> 0 | E7: =E6 -> 35154000 | F7: =F6 -> 33145200 | G7: =G6 -> 36605250 | H7: =H6 -> 43733250 | I7: =I6 -> 76848750 | J7: =J6 -> 72505125 | ... BJ7: =BJ6 -> 89262000
A8: B. FIXED OPERATING COSTS / CHI PHÍ CỐ ĐỊNH
A9: Rent / Thuê mặt bằng (VNĐ) | B9: =SUM(C9:AL9) -> 2070000000 | C9: ='⚙️ Assumptions'!$B$10 -> 57500000 | D9: ='⚙️ Assumptions'!$B$10 -> 57500000 | E9: ='⚙️ Assumptions'!$B$10 -> 57500000 | F9: ='⚙️ Assumptions'!$B$10 -> 57500000 | G9: ='⚙️ Assumptions'!$B$10 -> 57500000 | H9: ='⚙️ Assumptions'!$B$10 -> 57500000 | I9: ='⚙️ Assumptions'!$B$10 -> 57500000 | J9: ='⚙️ Assumptions'!$B$10 -> 57500000 | ... BJ9: ='⚙️ Assumptions'!$B$10 -> 57500000
A10: Utilities / Điện nước (VNĐ): | B10: =SUM(C10:AL10) -> 7.8973622e+08 | C10: =_xlfn.LET( _xlpm.Electric, C11, _xlpm.Water, C13, _xlpm.Electric + _xlpm.Water) -> 0 | D10: =_xlfn.LET( _xlpm.Electric, D11, _xlpm.Water, D13, _xlpm.Electric + _xlpm.Water) -> 0 | E10: =_xlfn.LET( _xlpm.Electric, E11, _xlpm.Water, E13, _xlpm.Electric + _xlpm.Water) -> 6403050 | F10: =_xlfn.LET( _xlpm.Electric, F11, _xlpm.Water, F13, _xlpm.Electric + _xlpm.Water) -> 6403050 | G10: =_xlfn.LET( _xlpm.Electric, G11, _xlpm.Water, G13, _xlpm.Electric + _xlpm.Water) -> 7626093.8 | H10: =_xlfn.LET( _xlpm.Electric, H11, _xlpm.Water, H13, _xlpm.Electric + _xlpm.Water) -> 9111093.8 | I10: =_xlfn.LET( _xlpm.Electric, I11, _xlpm.Water, I13, _xlpm.Electric + _xlpm.Water) -> 16010156 | J10: =_xlfn.LET( _xlpm.Electric, J11, _xlpm.Water, J13, _xlpm.Electric + _xlpm.Water) -> 15105234 | ... BJ10: =_xlfn.LET( _xlpm.Electric, BJ11, _xlpm.Water, BJ13, _xlpm.Electric + _xlpm.Water) -> 26547750
A11: - Tiền điện | B11: =SUM(C11:AL11) -> 6.0153019e+08 | C11: =_xlfn.LET( _xlpm.Electric_percent, _xlfn.IFNA(INDEX('⚙️ Assumptions'!$B$40:$F$40,MATCH(YEAR(C3),'⚙️ Assumptions'!$B$38:$F$38,0)),C12), _xlpm.Rev, INDEX('💰 Revenue'!$C$14:$BJ14,MATCH(C3,'💰 Revenue'!$C$5:$BJ$5,0)), _xlpm.Adj_ratio, INDEX('⚙️ Other Assumptions'!$B$15:$M$15,MATCH(MONTH(C3),'⚙️ Other Assumptions'!$B$14:$M$14)), _xlpm.Electric_percent * _xlpm.Rev * _xlpm.Adj_ratio) -> 0 | D11: =_xlfn.LET( _xlpm.Electric_percent, _xlfn.IFNA(INDEX('⚙️ Assumptions'!$B$40:$F$40,MATCH(YEAR(D3),'⚙️ Assumptions'!$B$38:$F$38,0)),D12), _xlpm.Rev, INDEX('💰 Revenue'!$C$14:$BJ14,MATCH(D3,'💰 Revenue'!$C$5:$BJ$5,0)), _xlpm.Adj_ratio, INDEX('⚙️ Other Assumptions'!$B$15:$M$15,MATCH(MONTH(D3),'⚙️ Other Assumptions'!$B$14:$M$14)), _xlpm.Electric_percent * _xlpm.Rev * _xlpm.Adj_ratio) -> 0 | E11: =_xlfn.LET( _xlpm.Electric_percent, _xlfn.IFNA(INDEX('⚙️ Assumptions'!$B$40:$F$40,MATCH(YEAR(E3),'⚙️ Assumptions'!$B$38:$F$38,0)),E12), _xlpm.Rev, INDEX('💰 Revenue'!$C$14:$BJ14,MATCH(E3,'💰 Revenue'!$C$5:$BJ$5,0)), _xlpm.Adj_ratio, INDEX('⚙️ Other Assumptions'!$B$15:$M$15,MATCH(MONTH(E3),'⚙️ Other Assumptions'!$B$14:$M$14)), _xlpm.Electric_percent * _xlpm.Rev * _xlpm.Adj_ratio) -> 4519800 | F11: =_xlfn.LET( _xlpm.Electric_percent, _xlfn.IFNA(INDEX('⚙️ Assumptions'!$B$40:$F$40,MATCH(YEAR(F3),'⚙️ Assumptions'!$B$38:$F$38,0)),F12), _xlpm.Rev, INDEX('💰 Revenue'!$C$14:$BJ14,MATCH(F3,'💰 Revenue'!$C$5:$BJ$5,0)), _xlpm.Adj_ratio, INDEX('⚙️ Other Assumptions'!$B$15:$M$15,MATCH(MONTH(F3),'⚙️ Other Assumptions'!$B$14:$M$14)), _xlpm.Electric_percent * _xlpm.Rev * _xlpm.Adj_ratio) -> 4519800 | G11: =_xlfn.LET( _xlpm.Electric_percent, _xlfn.IFNA(INDEX('⚙️ Assumptions'!$B$40:$F$40,MATCH(YEAR(G3),'⚙️ Assumptions'!$B$38:$F$38,0)),G12), _xlpm.Rev, INDEX('💰 Revenue'!$C$14:$BJ14,MATCH(G3,'💰 Revenue'!$C$5:$BJ$5,0)), _xlpm.Adj_ratio, INDEX('⚙️ Other Assumptions'!$B$15:$M$15,MATCH(MONTH(G3),'⚙️ Other Assumptions'!$B$14:$M$14)), _xlpm.Electric_percent * _xlpm.Rev * _xlpm.Adj_ratio) -> 5546250 | H11: =_xlfn.LET( _xlpm.Electric_percent, _xlfn.IFNA(INDEX('⚙️ Assumptions'!$B$40:$F$40,MATCH(YEAR(H3),'⚙️ Assumptions'!$B$38:$F$38,0)),H12), _xlpm.Rev, INDEX('💰 Revenue'!$C$14:$BJ14,MATCH(H3,'💰 Revenue'!$C$5:$BJ$5,0)), _xlpm.Adj_ratio, INDEX('⚙️ Other Assumptions'!$B$15:$M$15,MATCH(MONTH(H3),'⚙️ Other Assumptions'!$B$14:$M$14)), _xlpm.Electric_percent * _xlpm.Rev * _xlpm.Adj_ratio) -> 6626250 | I11: =_xlfn.LET( _xlpm.Electric_percent, _xlfn.IFNA(INDEX('⚙️ Assumptions'!$B$40:$F$40,MATCH(YEAR(I3),'⚙️ Assumptions'!$B$38:$F$38,0)),I12), _xlpm.Rev, INDEX('💰 Revenue'!$C$14:$BJ14,MATCH(I3,'💰 Revenue'!$C$5:$BJ$5,0)), _xlpm.Adj_ratio, INDEX('⚙️ Other Assumptions'!$B$15:$M$15,MATCH(MONTH(I3),'⚙️ Other Assumptions'!$B$14:$M$14)), _xlpm.Electric_percent * _xlpm.Rev * _xlpm.Adj_ratio) -> 11643750 | J11: =_xlfn.LET( _xlpm.Electric_percent, _xlfn.IFNA(INDEX('⚙️ Assumptions'!$B$40:$F$40,MATCH(YEAR(J3),'⚙️ Assumptions'!$B$38:$F$38,0)),J12), _xlpm.Rev, INDEX('💰 Revenue'!$C$14:$BJ14,MATCH(J3,'💰 Revenue'!$C$5:$BJ$5,0)), _xlpm.Adj_ratio, INDEX('⚙️ Other Assumptions'!$B$15:$M$15,MATCH(MONTH(J3),'⚙️ Other Assumptions'!$B$14:$M$14)), _xlpm.Electric_percent * _xlpm.Rev * _xlpm.Adj_ratio) -> 10985625 | ... BJ11: =_xlfn.LET( _xlpm.Electric_percent, _xlfn.IFNA(INDEX('⚙️ Assumptions'!$B$40:$F$40,MATCH(YEAR(BJ3),'⚙️ Assumptions'!$B$38:$F$38,0)),BJ12), _xlpm.Rev, INDEX('💰 Revenue'!$C$14:$BJ14,MATCH(BJ3,'💰 Revenue'!$C$5:$BJ$5,0)), _xlpm.Adj_ratio, INDEX('⚙️ Other Assumptions'!$B$15:$M$15,MATCH(MONTH(BJ3),'⚙️ Other Assumptions'!$B$14:$M$14)), _xlpm.Electric_percent * _xlpm.Rev * _xlpm.Adj_ratio) -> 20776500
A12: Tiền điện/ doanh thu | C12: =IF(_xlfn.IFNA(INDEX('⚙️ Assumptions'!$B$40:$F$40,MATCH(YEAR(C3),'⚙️ Assumptions'!$B$38:$F$38,0)),1)<>1,C11/INDEX('💰 Revenue'!$C$14:$BJ14,MATCH(C3,'💰 Revenue'!$C$5:$BJ$5,0)),OFFSET(C12,,-1)) -> #DIV/0! | D12: =IF(_xlfn.IFNA(INDEX('⚙️ Assumptions'!$B$40:$F$40,MATCH(YEAR(D3),'⚙️ Assumptions'!$B$38:$F$38,0)),1)<>1,D11/INDEX('💰 Revenue'!$C$14:$BJ14,MATCH(D3,'💰 Revenue'!$C$5:$BJ$5,0)),OFFSET(D12,,-1)) -> #DIV/0! | E12: =IF(_xlfn.IFNA(INDEX('⚙️ Assumptions'!$B$40:$F$40,MATCH(YEAR(E3),'⚙️ Assumptions'!$B$38:$F$38,0)),1)<>1,E11/INDEX('💰 Revenue'!$C$14:$BJ14,MATCH(E3,'💰 Revenue'!$C$5:$BJ$5,0)),OFFSET(E12,,-1)) -> 0.036 | F12: =IF(_xlfn.IFNA(INDEX('⚙️ Assumptions'!$B$40:$F$40,MATCH(YEAR(F3),'⚙️ Assumptions'!$B$38:$F$38,0)),1)<>1,F11/INDEX('💰 Revenue'!$C$14:$BJ14,MATCH(F3,'💰 Revenue'!$C$5:$BJ$5,0)),OFFSET(F12,,-1)) -> 0.036 | G12: =IF(_xlfn.IFNA(INDEX('⚙️ Assumptions'!$B$40:$F$40,MATCH(YEAR(G3),'⚙️ Assumptions'!$B$38:$F$38,0)),1)<>1,G11/INDEX('💰 Revenue'!$C$14:$BJ14,MATCH(G3,'💰 Revenue'!$C$5:$BJ$5,0)),OFFSET(G12,,-1)) -> 0.04 | H12: =IF(_xlfn.IFNA(INDEX('⚙️ Assumptions'!$B$40:$F$40,MATCH(YEAR(H3),'⚙️ Assumptions'!$B$38:$F$38,0)),1)<>1,H11/INDEX('💰 Revenue'!$C$14:$BJ14,MATCH(H3,'💰 Revenue'!$C$5:$BJ$5,0)),OFFSET(H12,,-1)) -> 0.04 | I12: =IF(_xlfn.IFNA(INDEX('⚙️ Assumptions'!$B$40:$F$40,MATCH(YEAR(I3),'⚙️ Assumptions'!$B$38:$F$38,0)),1)<>1,I11/INDEX('💰 Revenue'!$C$14:$BJ14,MATCH(I3,'💰 Revenue'!$C$5:$BJ$5,0)),OFFSET(I12,,-1)) -> 0.04 | J12: =IF(_xlfn.IFNA(INDEX('⚙️ Assumptions'!$B$40:$F$40,MATCH(YEAR(J3),'⚙️ Assumptions'!$B$38:$F$38,0)),1)<>1,J11/INDEX('💰 Revenue'!$C$14:$BJ14,MATCH(J3,'💰 Revenue'!$C$5:$BJ$5,0)),OFFSET(J12,,-1)) -> 0.04 | ... BJ12: =IF(_xlfn.IFNA(INDEX('⚙️ Assumptions'!$B$40:$F$40,MATCH(YEAR(BJ3),'⚙️ Assumptions'!$B$38:$F$38,0)),1)<>1,BJ11/INDEX('💰 Revenue'!$C$14:$BJ14,MATCH(BJ3,'💰 Revenue'!$C$5:$BJ$5,0)),OFFSET(BJ12,,-1)) -> 0.036
A13: - Tiền nước | B13: =SUM(C13:AL13) -> 1.8820603e+08 | C13: =_xlfn.LET( _xlpm.Water_percent,_xlfn.IFNA(INDEX('⚙️ Assumptions'!$B$41:$F$41,MATCH(YEAR(C3),'⚙️ Assumptions'!$B$38:$F$38,0)),OFFSET(C14,,-1)), _xlpm.rev,INDEX('💰 Revenue'!$C$14:$BJ$14,MATCH(C3,'💰 Revenue'!$C$5:$BJ$5,0)), _xlpm.Water_percent*_xlpm.rev) -> 0 | D13: =_xlfn.LET(_xlpm.Water_percent,_xlfn.IFNA(INDEX('⚙️ Assumptions'!$B$41:$F$41,MATCH(YEAR(D3),'⚙️ Assumptions'!$B$38:$F$38,0)),OFFSET(D14,,-1)),_xlpm.rev,INDEX('💰 Revenue'!$C$14:$BJ$14,MATCH(D3,'💰 Revenue'!$C$5:$BJ$5,0)),_xlpm.Water_percent*_xlpm.rev) -> 0 | E13: =_xlfn.LET(_xlpm.Water_percent,_xlfn.IFNA(INDEX('⚙️ Assumptions'!$B$41:$F$41,MATCH(YEAR(E3),'⚙️ Assumptions'!$B$38:$F$38,0)),OFFSET(E14,,-1)),_xlpm.rev,INDEX('💰 Revenue'!$C$14:$BJ$14,MATCH(E3,'💰 Revenue'!$C$5:$BJ$5,0)),_xlpm.Water_percent*_xlpm.rev) -> 1883250 | F13: =_xlfn.LET(_xlpm.Water_percent,_xlfn.IFNA(INDEX('⚙️ Assumptions'!$B$41:$F$41,MATCH(YEAR(F3),'⚙️ Assumptions'!$B$38:$F$38,0)),OFFSET(F14,,-1)),_xlpm.rev,INDEX('💰 Revenue'!$C$14:$BJ$14,MATCH(F3,'💰 Revenue'!$C$5:$BJ$5,0)),_xlpm.Water_percent*_xlpm.rev) -> 1883250 | G13: =_xlfn.LET(_xlpm.Water_percent,_xlfn.IFNA(INDEX('⚙️ Assumptions'!$B$41:$F$41,MATCH(YEAR(G3),'⚙️ Assumptions'!$B$38:$F$38,0)),OFFSET(G14,,-1)),_xlpm.rev,INDEX('💰 Revenue'!$C$14:$BJ$14,MATCH(G3,'💰 Revenue'!$C$5:$BJ$5,0)),_xlpm.Water_percent*_xlpm.rev) -> 2079843.8 | H13: =_xlfn.LET(_xlpm.Water_percent,_xlfn.IFNA(INDEX('⚙️ Assumptions'!$B$41:$F$41,MATCH(YEAR(H3),'⚙️ Assumptions'!$B$38:$F$38,0)),OFFSET(H14,,-1)),_xlpm.rev,INDEX('💰 Revenue'!$C$14:$BJ$14,MATCH(H3,'💰 Revenue'!$C$5:$BJ$5,0)),_xlpm.Water_percent*_xlpm.rev) -> 2484843.8 | I13: =_xlfn.LET(_xlpm.Water_percent,_xlfn.IFNA(INDEX('⚙️ Assumptions'!$B$41:$F$41,MATCH(YEAR(I3),'⚙️ Assumptions'!$B$38:$F$38,0)),OFFSET(I14,,-1)),_xlpm.rev,INDEX('💰 Revenue'!$C$14:$BJ$14,MATCH(I3,'💰 Revenue'!$C$5:$BJ$5,0)),_xlpm.Water_percent*_xlpm.rev) -> 4366406.2 | J13: =_xlfn.LET(_xlpm.Water_percent,_xlfn.IFNA(INDEX('⚙️ Assumptions'!$B$41:$F$41,MATCH(YEAR(J3),'⚙️ Assumptions'!$B$38:$F$38,0)),OFFSET(J14,,-1)),_xlpm.rev,INDEX('💰 Revenue'!$C$14:$BJ$14,MATCH(J3,'💰 Revenue'!$C$5:$BJ$5,0)),_xlpm.Water_percent*_xlpm.rev) -> 4119609.4 | K13: =_xlfn.LET(_xlpm.Water_percent,_xlfn.IFNA(INDEX('⚙️ Assumptions'!$B$41:$F$41,MATCH(YEAR(K3),'⚙️ Assumptions'!$B$38:$F$38,0)),OFFSET(K14,,-1)),_xlpm.rev,INDEX('💰 Revenue'!$C$14:$BJ$14,MATCH(K3,'💰 Revenue'!$C$5:$BJ$5,0)),_xlpm.Water_percent*_xlpm.rev) -> 4860000 | ... BJ13: =_xlfn.LET(_xlpm.Water_percent,_xlfn.IFNA(INDEX('⚙️ Assumptions'!$B$41:$F$41,MATCH(YEAR(BJ3),'⚙️ Assumptions'!$B$38:$F$38,0)),OFFSET(BJ14,,-1)),_xlpm.rev,INDEX('💰 Revenue'!$C$14:$BJ$14,MATCH(BJ3,'💰 Revenue'!$C$5:$BJ$5,0)),_xlpm.Water_percent*_xlpm.rev) -> 5771250
A14: Tiền nước/ doanh thu | C14: =IF(_xlfn.IFNA(INDEX('⚙️ Assumptions'!$B$40:$F$40,MATCH(YEAR(C3),'⚙️ Assumptions'!$B$38:$F$38,0)),1)<>1,C13/INDEX('💰 Revenue'!$C$14:$BJ14,MATCH(C3,'💰 Revenue'!$C$5:$BJ$5,0)),OFFSET(C14,,-1)) -> #DIV/0! | D14: =IF(_xlfn.IFNA(INDEX('⚙️ Assumptions'!$B$40:$F$40,MATCH(YEAR(D3),'⚙️ Assumptions'!$B$38:$F$38,0)),1)<>1,D13/INDEX('💰 Revenue'!$C$14:$BJ14,MATCH(D3,'💰 Revenue'!$C$5:$BJ$5,0)),OFFSET(D14,,-1)) -> #DIV/0! | E14: =IF(_xlfn.IFNA(INDEX('⚙️ Assumptions'!$B$40:$F$40,MATCH(YEAR(E3),'⚙️ Assumptions'!$B$38:$F$38,0)),1)<>1,E13/INDEX('💰 Revenue'!$C$14:$BJ14,MATCH(E3,'💰 Revenue'!$C$5:$BJ$5,0)),OFFSET(E14,,-1)) -> 0.015 | F14: =IF(_xlfn.IFNA(INDEX('⚙️ Assumptions'!$B$40:$F$40,MATCH(YEAR(F3),'⚙️ Assumptions'!$B$38:$F$38,0)),1)<>1,F13/INDEX('💰 Revenue'!$C$14:$BJ14,MATCH(F3,'💰 Revenue'!$C$5:$BJ$5,0)),OFFSET(F14,,-1)) -> 0.015 | G14: =IF(_xlfn.IFNA(INDEX('⚙️ Assumptions'!$B$40:$F$40,MATCH(YEAR(G3),'⚙️ Assumptions'!$B$38:$F$38,0)),1)<>1,G13/INDEX('💰 Revenue'!$C$14:$BJ14,MATCH(G3,'💰 Revenue'!$C$5:$BJ$5,0)),OFFSET(G14,,-1)) -> 0.015 | H14: =IF(_xlfn.IFNA(INDEX('⚙️ Assumptions'!$B$40:$F$40,MATCH(YEAR(H3),'⚙️ Assumptions'!$B$38:$F$38,0)),1)<>1,H13/INDEX('💰 Revenue'!$C$14:$BJ14,MATCH(H3,'💰 Revenue'!$C$5:$BJ$5,0)),OFFSET(H14,,-1)) -> 0.015 | I14: =IF(_xlfn.IFNA(INDEX('⚙️ Assumptions'!$B$40:$F$40,MATCH(YEAR(I3),'⚙️ Assumptions'!$B$38:$F$38,0)),1)<>1,I13/INDEX('💰 Revenue'!$C$14:$BJ14,MATCH(I3,'💰 Revenue'!$C$5:$BJ$5,0)),OFFSET(I14,,-1)) -> 0.015 | J14: =IF(_xlfn.IFNA(INDEX('⚙️ Assumptions'!$B$40:$F$40,MATCH(YEAR(J3),'⚙️ Assumptions'!$B$38:$F$38,0)),1)<>1,J13/INDEX('💰 Revenue'!$C$14:$BJ14,MATCH(J3,'💰 Revenue'!$C$5:$BJ$5,0)),OFFSET(J14,,-1)) -> 0.015 | ... BJ14: =IF(_xlfn.IFNA(INDEX('⚙️ Assumptions'!$B$40:$F$40,MATCH(YEAR(BJ3),'⚙️ Assumptions'!$B$38:$F$38,0)),1)<>1,BJ13/INDEX('💰 Revenue'!$C$14:$BJ14,MATCH(BJ3,'💰 Revenue'!$C$5:$BJ$5,0)),OFFSET(BJ14,,-1)) -> 0.015
A15: Maintainace / Sửa chữa (VNĐ) | B15: =SUM(C15:AL15) -> 3.0616819e+08 | C15: =_xlfn.LET( _xlpm.Maintainance_ratio,_xlfn.IFNA(INDEX('⚙️ Assumptions'!$B$42:$F$42,MATCH(YEAR(C3),'⚙️ Assumptions'!$B$38:F$38,0)),OFFSET(C16,,-1)), _xlpm.rev,INDEX('💰 Revenue'!$C$14:$BJ$14,MATCH(C3,'💰 Revenue'!$C$5:$BJ$5,0)), _xlpm.Maintainance_ratio*_xlpm.rev) -> 0 | D15: =_xlfn.LET(_xlpm.Maintainance_ratio,_xlfn.IFNA(INDEX('⚙️ Assumptions'!$B$42:$F$42,MATCH(YEAR(D3),'⚙️ Assumptions'!$B$38:G$38,0)),OFFSET(D16,,-1)),_xlpm.rev,INDEX('💰 Revenue'!$C$14:$BJ$14,MATCH(D3,'💰 Revenue'!$C$5:$BJ$5,0)),_xlpm.Maintainance_ratio*_xlpm.rev) -> 0 | E15: =_xlfn.LET(_xlpm.Maintainance_ratio,_xlfn.IFNA(INDEX('⚙️ Assumptions'!$B$42:$F$42,MATCH(YEAR(E3),'⚙️ Assumptions'!$B$38:H$38,0)),OFFSET(E16,,-1)),_xlpm.rev,INDEX('💰 Revenue'!$C$14:$BJ$14,MATCH(E3,'💰 Revenue'!$C$5:$BJ$5,0)),_xlpm.Maintainance_ratio*_xlpm.rev) -> 1255500 | F15: =_xlfn.LET(_xlpm.Maintainance_ratio,_xlfn.IFNA(INDEX('⚙️ Assumptions'!$B$42:$F$42,MATCH(YEAR(F3),'⚙️ Assumptions'!$B$38:I$38,0)),OFFSET(F16,,-1)),_xlpm.rev,INDEX('💰 Revenue'!$C$14:$BJ$14,MATCH(F3,'💰 Revenue'!$C$5:$BJ$5,0)),_xlpm.Maintainance_ratio*_xlpm.rev) -> 1255500 | G15: =_xlfn.LET(_xlpm.Maintainance_ratio,_xlfn.IFNA(INDEX('⚙️ Assumptions'!$B$42:$F$42,MATCH(YEAR(G3),'⚙️ Assumptions'!$B$38:J$38,0)),OFFSET(G16,,-1)),_xlpm.rev,INDEX('💰 Revenue'!$C$14:$BJ$14,MATCH(G3,'💰 Revenue'!$C$5:$BJ$5,0)),_xlpm.Maintainance_ratio*_xlpm.rev) -> 1386562.5 | H15: =_xlfn.LET(_xlpm.Maintainance_ratio,_xlfn.IFNA(INDEX('⚙️ Assumptions'!$B$42:$F$42,MATCH(YEAR(H3),'⚙️ Assumptions'!$B$38:K$38,0)),OFFSET(H16,,-1)),_xlpm.rev,INDEX('💰 Revenue'!$C$14:$BJ$14,MATCH(H3,'💰 Revenue'!$C$5:$BJ$5,0)),_xlpm.Maintainance_ratio*_xlpm.rev) -> 1656562.5 | I15: =_xlfn.LET(_xlpm.Maintainance_ratio,_xlfn.IFNA(INDEX('⚙️ Assumptions'!$B$42:$F$42,MATCH(YEAR(I3),'⚙️ Assumptions'!$B$38:L$38,0)),OFFSET(I16,,-1)),_xlpm.rev,INDEX('💰 Revenue'!$C$14:$BJ$14,MATCH(I3,'💰 Revenue'!$C$5:$BJ$5,0)),_xlpm.Maintainance_ratio*_xlpm.rev) -> 2910937.5 | J15: =_xlfn.LET(_xlpm.Maintainance_ratio,_xlfn.IFNA(INDEX('⚙️ Assumptions'!$B$42:$F$42,MATCH(YEAR(J3),'⚙️ Assumptions'!$B$38:M$38,0)),OFFSET(J16,,-1)),_xlpm.rev,INDEX('💰 Revenue'!$C$14:$BJ$14,MATCH(J3,'💰 Revenue'!$C$5:$BJ$5,0)),_xlpm.Maintainance_ratio*_xlpm.rev) -> 2746406.2 | K15: =_xlfn.LET(_xlpm.Maintainance_ratio,_xlfn.IFNA(INDEX('⚙️ Assumptions'!$B$42:$F$42,MATCH(YEAR(K3),'⚙️ Assumptions'!$B$38:N$38,0)),OFFSET(K16,,-1)),_xlpm.rev,INDEX('💰 Revenue'!$C$14:$BJ$14,MATCH(K3,'💰 Revenue'!$C$5:$BJ$5,0)),_xlpm.Maintainance_ratio*_xlpm.rev) -> 3240000 | ... BJ15: =_xlfn.LET(_xlpm.Maintainance_ratio,_xlfn.IFNA(INDEX('⚙️ Assumptions'!$B$42:$F$42,MATCH(YEAR(BJ3),'⚙️ Assumptions'!$B$38:BM$38,0)),OFFSET(BJ16,,-1)),_xlpm.rev,INDEX('💰 Revenue'!$C$14:$BJ$14,MATCH(BJ3,'💰 Revenue'!$C$5:$BJ$5,0)),_xlpm.Maintainance_ratio*_xlpm.rev) -> 15390000
A16: Maintainance/doanh thu | C16: =IF(_xlfn.IFNA(INDEX('⚙️ Assumptions'!$B$40:$F$40,MATCH(YEAR(C3),'⚙️ Assumptions'!$B$38:$F$38,0)),1)<>1,C15/INDEX('💰 Revenue'!$C$14:$BJ14,MATCH(C3,'💰 Revenue'!$C$5:$BJ$5,0)),OFFSET(C16,,-1)) -> #DIV/0! | D16: =IF(_xlfn.IFNA(INDEX('⚙️ Assumptions'!$B$40:$F$40,MATCH(YEAR(D3),'⚙️ Assumptions'!$B$38:$F$38,0)),1)<>1,D15/INDEX('💰 Revenue'!$C$14:$BJ14,MATCH(D3,'💰 Revenue'!$C$5:$BJ$5,0)),OFFSET(D16,,-1)) -> #DIV/0! | E16: =IF(_xlfn.IFNA(INDEX('⚙️ Assumptions'!$B$40:$F$40,MATCH(YEAR(E3),'⚙️ Assumptions'!$B$38:$F$38,0)),1)<>1,E15/INDEX('💰 Revenue'!$C$14:$BJ14,MATCH(E3,'💰 Revenue'!$C$5:$BJ$5,0)),OFFSET(E16,,-1)) -> 0.01 | F16: =IF(_xlfn.IFNA(INDEX('⚙️ Assumptions'!$B$40:$F$40,MATCH(YEAR(F3),'⚙️ Assumptions'!$B$38:$F$38,0)),1)<>1,F15/INDEX('💰 Revenue'!$C$14:$BJ14,MATCH(F3,'💰 Revenue'!$C$5:$BJ$5,0)),OFFSET(F16,,-1)) -> 0.01 | G16: =IF(_xlfn.IFNA(INDEX('⚙️ Assumptions'!$B$40:$F$40,MATCH(YEAR(G3),'⚙️ Assumptions'!$B$38:$F$38,0)),1)<>1,G15/INDEX('💰 Revenue'!$C$14:$BJ14,MATCH(G3,'💰 Revenue'!$C$5:$BJ$5,0)),OFFSET(G16,,-1)) -> 0.01 | H16: =IF(_xlfn.IFNA(INDEX('⚙️ Assumptions'!$B$40:$F$40,MATCH(YEAR(H3),'⚙️ Assumptions'!$B$38:$F$38,0)),1)<>1,H15/INDEX('💰 Revenue'!$C$14:$BJ14,MATCH(H3,'💰 Revenue'!$C$5:$BJ$5,0)),OFFSET(H16,,-1)) -> 0.01 | I16: =IF(_xlfn.IFNA(INDEX('⚙️ Assumptions'!$B$40:$F$40,MATCH(YEAR(I3),'⚙️ Assumptions'!$B$38:$F$38,0)),1)<>1,I15/INDEX('💰 Revenue'!$C$14:$BJ14,MATCH(I3,'💰 Revenue'!$C$5:$BJ$5,0)),OFFSET(I16,,-1)) -> 0.01 | J16: =IF(_xlfn.IFNA(INDEX('⚙️ Assumptions'!$B$40:$F$40,MATCH(YEAR(J3),'⚙️ Assumptions'!$B$38:$F$38,0)),1)<>1,J15/INDEX('💰 Revenue'!$C$14:$BJ14,MATCH(J3,'💰 Revenue'!$C$5:$BJ$5,0)),OFFSET(J16,,-1)) -> 0.01 | ... BJ16: =IF(_xlfn.IFNA(INDEX('⚙️ Assumptions'!$B$40:$F$40,MATCH(YEAR(BJ3),'⚙️ Assumptions'!$B$38:$F$38,0)),1)<>1,BJ15/INDEX('💰 Revenue'!$C$14:$BJ14,MATCH(BJ3,'💰 Revenue'!$C$5:$BJ$5,0)),OFFSET(BJ16,,-1)) -> 0.04
A17: Payroll / Lương (VNĐ) — from HR Plan | B17: =SUM(C17:AL17) -> 1254820000 | C17: =INDEX('👥 HR Plan'!$B$18:$BI$18,MATCH(C3,'👥 HR Plan'!$B$11:$BI$11,0)) -> 0 | D17: =INDEX('👥 HR Plan'!$B$18:$BI$18,MATCH(D3,'👥 HR Plan'!$B$11:$BI$11,0)) -> 0 | E17: =INDEX('👥 HR Plan'!$B$18:$BI$18,MATCH(E3,'👥 HR Plan'!$B$11:$BI$11,0)) -> 28276000 | F17: =INDEX('👥 HR Plan'!$B$18:$BI$18,MATCH(F3,'👥 HR Plan'!$B$11:$BI$11,0)) -> 28276000 | G17: =INDEX('👥 HR Plan'!$B$18:$BI$18,MATCH(G3,'👥 HR Plan'!$B$11:$BI$11,0)) -> 27484000 | H17: =INDEX('👥 HR Plan'!$B$18:$BI$18,MATCH(H3,'👥 HR Plan'!$B$11:$BI$11,0)) -> 28276000 | I17: =INDEX('👥 HR Plan'!$B$18:$BI$18,MATCH(I3,'👥 HR Plan'!$B$11:$BI$11,0)) -> 33820000 | J17: =INDEX('👥 HR Plan'!$B$18:$BI$18,MATCH(J3,'👥 HR Plan'!$B$11:$BI$11,0)) -> 34414000 | ... BJ17: =INDEX('👥 HR Plan'!$B$18:$BI$18,MATCH(BJ3,'👥 HR Plan'!$B$11:$BI$11,0)) -> 39760000
A18: Marketing / Quảng cáo (VNĐ) | B18: =SUM(C18:AL18) -> 491743125 | C18: =IFERROR(INDEX('⚙️ Other Assumptions'!$C$20:$AJ$20,MATCH('💰 Revenue'!C4,'⚙️ Other Assumptions'!$B$14:$AI$14,0)),'⚙️ Other Assumptions'!$B$23) * INDEX('💰 Revenue'!$C$14:$BJ$14,MATCH(C3,'💰 Revenue'!$C$5:$BJ$5,0)) -> 0 | D18: =IFERROR(INDEX('⚙️ Other Assumptions'!$C$20:$AJ$20,MATCH('💰 Revenue'!D4,'⚙️ Other Assumptions'!$B$14:$AI$14,0)),'⚙️ Other Assumptions'!$B$23) * INDEX('💰 Revenue'!$C$14:$BJ$14,MATCH(D3,'💰 Revenue'!$C$5:$BJ$5,0)) -> 0 | E18: =IFERROR(INDEX('⚙️ Other Assumptions'!$C$20:$AJ$20,MATCH('💰 Revenue'!E4,'⚙️ Other Assumptions'!$B$14:$AI$14,0)),'⚙️ Other Assumptions'!$B$23) * INDEX('💰 Revenue'!$C$14:$BJ$14,MATCH(E3,'💰 Revenue'!$C$5:$BJ$5,0)) -> 25110000 | F18: =IFERROR(INDEX('⚙️ Other Assumptions'!$C$20:$AJ$20,MATCH('💰 Revenue'!F4,'⚙️ Other Assumptions'!$B$14:$AI$14,0)),'⚙️ Other Assumptions'!$B$23) * INDEX('💰 Revenue'!$C$14:$BJ$14,MATCH(F3,'💰 Revenue'!$C$5:$BJ$5,0)) -> 25110000 | G18: =IFERROR(INDEX('⚙️ Other Assumptions'!$C$20:$AJ$20,MATCH('💰 Revenue'!G4,'⚙️ Other Assumptions'!$B$14:$AI$14,0)),'⚙️ Other Assumptions'!$B$23) * INDEX('💰 Revenue'!$C$14:$BJ$14,MATCH(G3,'💰 Revenue'!$C$5:$BJ$5,0)) -> 11092500 | H18: =IFERROR(INDEX('⚙️ Other Assumptions'!$C$20:$AJ$20,MATCH('💰 Revenue'!H4,'⚙️ Other Assumptions'!$B$14:$AI$14,0)),'⚙️ Other Assumptions'!$B$23) * INDEX('💰 Revenue'!$C$14:$BJ$14,MATCH(H3,'💰 Revenue'!$C$5:$BJ$5,0)) -> 13252500 | I18: =IFERROR(INDEX('⚙️ Other Assumptions'!$C$20:$AJ$20,MATCH('💰 Revenue'!I4,'⚙️ Other Assumptions'!$B$14:$AI$14,0)),'⚙️ Other Assumptions'!$B$23) * INDEX('💰 Revenue'!$C$14:$BJ$14,MATCH(I3,'💰 Revenue'!$C$5:$BJ$5,0)) -> 23287500 | J18: =IFERROR(INDEX('⚙️ Other Assumptions'!$C$20:$AJ$20,MATCH('💰 Revenue'!J4,'⚙️ Other Assumptions'!$B$14:$AI$14,0)),'⚙️ Other Assumptions'!$B$23) * INDEX('💰 Revenue'!$C$14:$BJ$14,MATCH(J3,'💰 Revenue'!$C$5:$BJ$5,0)) -> 21971250 | ... BJ18: =IFERROR(INDEX('⚙️ Other Assumptions'!$C$20:$AJ$20,MATCH('💰 Revenue'!BJ4,'⚙️ Other Assumptions'!$B$14:$AI$14,0)),'⚙️ Other Assumptions'!$B$23) * INDEX('💰 Revenue'!$C$14:$BJ$14,MATCH(BJ3,'💰 Revenue'!$C$5:$BJ$5,0)) -> 11542500
A19: Other fixed / Chi phí cố định khác (VNĐ) | B19: =SUM(C19:AL19) -> 0
A20: TOTAL FIXED COSTS / TỔNG CP CỐ ĐỊNH (VNĐ) | B20: =SUM(C20:AL20) -> 4.9124675e+09 | C20: =C9+C10+C15+C17+C18+C19 -> 57500000 | D20: =D9+D10+D15+D17+D18+D19 -> 57500000 | E20: =E9+E10+E15+E17+E18+E19 -> 118544550 | F20: =F9+F10+F15+F17+F18+F19 -> 118544550 | G20: =G9+G10+G15+G17+G18+G19 -> 1.0508916e+08 | H20: =H9+H10+H15+H17+H18+H19 -> 1.0979616e+08 | I20: =I9+I10+I15+I17+I18+I19 -> 1.3352859e+08 | J20: =J9+J10+J15+J17+J18+J19 -> 1.3173689e+08 | ... BJ20: =BJ9+BJ10+BJ15+BJ17+BJ18+BJ19 -> 150740250
A21: C. VARIABLE OVERHEAD / CHI PHÍ BIẾN ĐỔI CHUNG
A22: Loyalty program cost / CP chương trình thành viên (VNĐ) | B22: =SUM(C22:AL22) -> 0
A23: Promotions / Khuyến mãi (VNĐ) | B23: =SUM(C23:AL23) -> 0
A24: Opex sub-total (before contingency) | B24: =SUM(C24:AL24) -> 4.9124675e+09 | C24: =C20+C22+C23 -> 57500000 | D24: =D20+D22+D23 -> 57500000 | E24: =E20+E22+E23 -> 118544550 | F24: =F20+F22+F23 -> 118544550 | G24: =G20+G22+G23 -> 1.0508916e+08 | H24: =H20+H22+H23 -> 1.0979616e+08 | I24: =I20+I22+I23 -> 1.3352859e+08 | J24: =J20+J22+J23 -> 1.3173689e+08 | ... BJ24: =BJ20+BJ22+BJ23 -> 150740250
A25: Contingency 2% / Dự phòng phí (VNĐ) | B25: =SUM(C25:AL25) -> 98249351 | C25: =C24*0.02 -> 1150000 | D25: =D24*0.02 -> 1150000 | E25: =E24*0.02 -> 2370891 | F25: =F24*0.02 -> 2370891 | G25: =G24*0.02 -> 2101783.1 | H25: =H24*0.02 -> 2195923.1 | I25: =I24*0.02 -> 2670571.9 | J25: =J24*0.02 -> 2634737.8 | ... BJ25: =BJ24*0.02 -> 3014805
A26: Management fee 3% / Phí quản lý (VNĐ) | B26: =SUM(C26:AL26) -> 1.4737403e+08 | C26: =C24*0.03 -> 1725000 | D26: =D24*0.03 -> 1725000 | E26: =E24*0.03 -> 3556336.5 | F26: =F24*0.03 -> 3556336.5 | G26: =G24*0.03 -> 3152674.7 | H26: =H24*0.03 -> 3293884.7 | I26: =I24*0.03 -> 4005857.8 | J26: =J24*0.03 -> 3952106.7 | ... BJ26: =BJ24*0.03 -> 4522207.5
A27: TOTAL VARIABLE OVERHEAD / TỔNG CP BIẾN ĐỔI (VNĐ) | B27: =SUM(C27:AL27) -> 2.4562338e+08 | C27: =C22+C23+C25+C26 -> 2875000 | D27: =D22+D23+D25+D26 -> 2875000 | E27: =E22+E23+E25+E26 -> 5927227.5 | F27: =F22+F23+F25+F26 -> 5927227.5 | G27: =G22+G23+G25+G26 -> 5254457.8 | H27: =H22+H23+H25+H26 -> 5489807.8 | I27: =I22+I23+I25+I26 -> 6676429.7 | J27: =J22+J23+J25+J26 -> 6586844.5 | ... BJ27: =BJ22+BJ23+BJ25+BJ26 -> 7537012.5
A28: D. CAPEX & DEPRECIATION / ĐẦU TƯ & KHẤU HAO
A29: Capital expenditure / Chi phí đầu tư (VNĐ) | B29: =SUM(C29:AL29) -> 300000000 | C29: ='⚙️ Assumptions'!$B$16 -> 300000000
A30: Monthly depreciation / Khấu hao hàng tháng (VNĐ) | B30: =SUM(C30:AL30) -> 180000000 | C30: =$C$29/12/5 -> 5000000 | D30: =$C$29/12/5 -> 5000000 | E30: =$C$29/12/5 -> 5000000 | F30: =$C$29/12/5 -> 5000000 | G30: =$C$29/12/5 -> 5000000 | H30: =$C$29/12/5 -> 5000000 | I30: =$C$29/12/5 -> 5000000 | J30: =$C$29/12/5 -> 5000000 | ... BJ30: =$C$29/12/5 -> 5000000
A31: E. TOTAL COST SUMMARY / TỔNG CHI PHÍ
A32: TOTAL OPEX (excl. Capex) / TỔNG CP VH (VNĐ) | B32: =SUM(C32:AL32) -> 8.2245147e+09 | C32: =C7+C20+C27 -> 60375000 | D32: =D7+D20+D27 -> 60375000 | E32: =E7+E20+E27 -> 1.5962578e+08 | F32: =F7+F20+F27 -> 1.5761698e+08 | G32: =G7+G20+G27 -> 1.4694886e+08 | H32: =H7+H20+H27 -> 1.5901921e+08 | I32: =I7+I20+I27 -> 2.1705377e+08 | J32: =J7+J20+J27 -> 2.1082886e+08 | ... BJ32: =BJ7+BJ20+BJ27 -> 2.4753926e+08
A33: TOTAL COST incl. Capex / TỔNG CHI PHÍ (VNĐ) | B33: =SUM(C33:AL33) -> 8.5245147e+09 | C33: =C32+C29 -> 360375000 | D33: =D32+D29 -> 60375000 | E33: =E32+E29 -> 1.5962578e+08 | F33: =F32+F29 -> 1.5761698e+08 | G33: =G32+G29 -> 1.4694886e+08 | H33: =H32+H29 -> 1.5901921e+08 | I33: =I32+I29 -> 2.1705377e+08 | J33: =J32+J29 -> 2.1082886e+08 | ... BJ33: =BJ32+BJ29 -> 2.4753926e+08
A34: Total opex % revenue / Tổng CP % DT | B34: ="" | C34: =IFERROR(C32/INDEX('💰 Revenue'!$C$19:$BJ$19,MATCH(C3,'💰 Revenue'!$C$5:BJ5,0)),"-") -> - | D34: =IFERROR(D32/INDEX('💰 Revenue'!$C$19:$BJ$19,MATCH(D3,'💰 Revenue'!$C$5:BK5,0)),"-") -> - | E34: =IFERROR(E32/INDEX('💰 Revenue'!$C$19:$BJ$19,MATCH(E3,'💰 Revenue'!$C$5:BL5,0)),"-") -> 1.271412 | F34: =IFERROR(F32/INDEX('💰 Revenue'!$C$19:$BJ$19,MATCH(F3,'💰 Revenue'!$C$5:BM5,0)),"-") -> 1.255412 | G34: =IFERROR(G32/INDEX('💰 Revenue'!$C$19:$BJ$19,MATCH(G3,'💰 Revenue'!$C$5:BN5,0)),"-") -> 1.059807 | H34: =IFERROR(H32/INDEX('💰 Revenue'!$C$19:$BJ$19,MATCH(H3,'💰 Revenue'!$C$5:BO5,0)),"-") -> 0.95993489 | I34: =IFERROR(I32/INDEX('💰 Revenue'!$C$19:$BJ$19,MATCH(I3,'💰 Revenue'!$C$5:BP5,0)),"-") -> 0.74564903 | J34: =IFERROR(J32/INDEX('💰 Revenue'!$C$19:$BJ$19,MATCH(J3,'💰 Revenue'!$C$5:BQ5,0)),"-") -> 0.76765358 | ... BJ34: =IFERROR(BJ32/INDEX('💰 Revenue'!$C$19:$BJ$19,MATCH(BJ3,'💰 Revenue'!$C$5:DQ5,0)),"-") -> 0.6433769

Sheet 👥 HR Plan
A1: HR PLAN & PAYROLL BUDGET / KẾ HOẠCH NHÂN SỰ & LƯƠNG
A2: POSITION / CHỨC VỤ | B2: Qty/ Số lượng | C2: SALARY Incl Insurance (Lương đã bao gồm bảo hiểm) | D2: Hourly Rate (Lương trên giờ) | F2: SHIFTS SỐ CA | G2: NOTES / GHI CHÚ
A3: General Manager / Quản lý nhà hàng | B3: 1 | C3: =12*10^6 -> 12000000
A4: Waiter/Waitress / Phục vụ bàn | D4: 33000 | F4: 2 shifts per day
A5: Security / Bảo vệ (outsouce) | B5: 0 | C5: 8500000
A6: Accountant / Kế toán (Outsource) | C6: =4*10^6 -> 4000000
A8: TOTAL HEADCOUNT / TỔNG NHÂN VIÊN | B8: =SUMPRODUCT((LEN(A3:A6)>0)*(B3:B6)) -> 1 | C8: =SUMPRODUCT((LEN(A3:A6)>0)*(C3:C6)) -> 24500000 | D8: =SUMPRODUCT((LEN(A3:A6)>0)*(D3:D6)) -> 33000
B10: 1 | C10: 2 | D10: 3 | E10: 4 | F10: 5 | G10: 6 | H10: 7 | I10: 8 | J10: 9 | K10: 10 | L10: 11 | M10: 12 | N10: 13 | O10: 14 | P10: 15 | Q10: 16 | R10: 17 | S10: 18 | T10: 19 | U10: 20 | V10: 21 | W10: 22 | X10: 23 | Y10: 24 | Z10: 25 | AA10: 26 | AB10: 27 | AC10: 28 | AD10: 29 | AE10: 30 | AF10: 31 | AG10: 32 | AH10: 33 | AI10: 34 | AJ10: 35 | AK10: 36 | AL10: 37 | AM10: 38 | AN10: 39 | AO10: 40 | AP10: 41 | AQ10: 42 | AR10: 43 | AS10: 44 | AT10: 45 | AU10: 46 | AV10: 47 | AW10: 48 | AX10: 49 | AY10: 50 | AZ10: 51 | BA10: 52 | BB10: 53 | BC10: 54 | BD10: 55 | BE10: 56 | BF10: 57 | BG10: 58 | BH10: 59 | BI10: 60
B11: ='⚙️ Assumptions'!B6 -> 46661 | C11: =EDATE($B$11,'💰 Revenue'!D2) -> 46692 | D11: =EDATE($B$11,'💰 Revenue'!E2) -> 46722 | E11: =EDATE($B$11,'💰 Revenue'!F2) -> 46753 | F11: =EDATE($B$11,'💰 Revenue'!G2) -> 46784 | G11: =EDATE($B$11,'💰 Revenue'!H2) -> 46813 | H11: =EDATE($B$11,'💰 Revenue'!I2) -> 46844 | I11: =EDATE($B$11,'💰 Revenue'!J2) -> 46874 | J11: =EDATE($B$11,'💰 Revenue'!K2) -> 46905 | ... BI11: =EDATE($B$11,'💰 Revenue'!BJ2) -> 48458
A12: General Manager/ Main Cook | B12: =_xlfn.LET( _xlpm.prep_month, INDEX('⚙️ Other Assumptions'!$B$18:$AK$18,MATCH(B$10,'⚙️ Other Assumptions'!$B$14:$AK$14,0)), IF(B$10> 10, $C$3, IF( _xlpm.prep_month >0, $C$3,0))) -> 0 | C12: =_xlfn.LET( _xlpm.prep_month, INDEX('⚙️ Other Assumptions'!$B$18:$AK$18,MATCH(C$10,'⚙️ Other Assumptions'!$B$14:$AK$14,0)), IF(C$10> 10, $C$3, IF( _xlpm.prep_month >0, $C$3,0))) -> 0 | D12: =_xlfn.LET( _xlpm.prep_month, INDEX('⚙️ Other Assumptions'!$B$18:$AK$18,MATCH(D$10,'⚙️ Other Assumptions'!$B$14:$AK$14,0)), IF(D$10> 10, $C$3, IF( _xlpm.prep_month >0, $C$3,0))) -> 12000000 | E12: =_xlfn.LET( _xlpm.prep_month, INDEX('⚙️ Other Assumptions'!$B$18:$AK$18,MATCH(E$10,'⚙️ Other Assumptions'!$B$14:$AK$14,0)), IF(E$10> 10, $C$3, IF( _xlpm.prep_month >0, $C$3,0))) -> 12000000 | F12: =_xlfn.LET( _xlpm.prep_month, INDEX('⚙️ Other Assumptions'!$B$18:$AK$18,MATCH(F$10,'⚙️ Other Assumptions'!$B$14:$AK$14,0)), IF(F$10> 10, $C$3, IF( _xlpm.prep_month >0, $C$3,0))) -> 12000000 | G12: =_xlfn.LET( _xlpm.prep_month, INDEX('⚙️ Other Assumptions'!$B$18:$AK$18,MATCH(G$10,'⚙️ Other Assumptions'!$B$14:$AK$14,0)), IF(G$10> 10, $C$3, IF( _xlpm.prep_month >0, $C$3,0))) -> 12000000 | H12: =_xlfn.LET( _xlpm.prep_month, INDEX('⚙️ Other Assumptions'!$B$18:$AK$18,MATCH(H$10,'⚙️ Other Assumptions'!$B$14:$AK$14,0)), IF(H$10> 10, $C$3, IF( _xlpm.prep_month >0, $C$3,0))) -> 12000000 | I12: =_xlfn.LET( _xlpm.prep_month, INDEX('⚙️ Other Assumptions'!$B$18:$AK$18,MATCH(I$10,'⚙️ Other Assumptions'!$B$14:$AK$14,0)), IF(I$10> 10, $C$3, IF( _xlpm.prep_month >0, $C$3,0))) -> 12000000 | ... BI12: =_xlfn.LET( _xlpm.prep_month, INDEX('⚙️ Other Assumptions'!$B$18:$AK$18,MATCH(BI$10,'⚙️ Other Assumptions'!$B$14:$AK$14,0)), IF(BI$10> 10, $C$3, IF( _xlpm.prep_month >0, $C$3,0))) -> 12000000
A13: # of Waiter/Waitress / Phục vụ bàn | B13: =IF(B14>150,4,IF(B14>100,3,IF(B14>0,2,0))) -> 0 | C13: =IF(C14>150,4,IF(C14>100,3,IF(C14>0,2,0))) -> 0 | D13: =IF(D14>150,4,IF(D14>100,3,IF(D14>0,2,0))) -> 2 | E13: =IF(E14>150,4,IF(E14>100,3,IF(E14>0,2,0))) -> 2 | F13: =IF(F14>150,4,IF(F14>100,3,IF(F14>0,2,0))) -> 2 | G13: =IF(G14>150,4,IF(G14>100,3,IF(G14>0,2,0))) -> 2 | H13: =IF(H14>150,4,IF(H14>100,3,IF(H14>0,2,0))) -> 3 | I13: =IF(I14>150,4,IF(I14>100,3,IF(I14>0,2,0))) -> 3 | ... BI13: =IF(BI14>150,4,IF(BI14>100,3,IF(BI14>0,2,0))) -> 4
A14: Number of covers | B14: =INDEX('💰 Revenue'!$C$7:$BJ$7, MATCH(B11,'💰 Revenue'!$C$5:$BJ$5,0)) -> 0 | C14: =INDEX('💰 Revenue'!$C$7:$BJ$7, MATCH(C11,'💰 Revenue'!$C$5:$BJ$5,0)) -> 0 | D14: =INDEX('💰 Revenue'!$C$7:$BJ$7, MATCH(D11,'💰 Revenue'!$C$5:$BJ$5,0)) -> 45 | E14: =INDEX('💰 Revenue'!$C$7:$BJ$7, MATCH(E11,'💰 Revenue'!$C$5:$BJ$5,0)) -> 45 | F14: =INDEX('💰 Revenue'!$C$7:$BJ$7, MATCH(F11,'💰 Revenue'!$C$5:$BJ$5,0)) -> 75 | G14: =INDEX('💰 Revenue'!$C$7:$BJ$7, MATCH(G11,'💰 Revenue'!$C$5:$BJ$5,0)) -> 75 | H14: =INDEX('💰 Revenue'!$C$7:$BJ$7, MATCH(H11,'💰 Revenue'!$C$5:$BJ$5,0)) -> 112.5 | I14: =INDEX('💰 Revenue'!$C$7:$BJ$7, MATCH(I11,'💰 Revenue'!$C$5:$BJ$5,0)) -> 112.5 | ... BI14: =INDEX('💰 Revenue'!$C$7:$BJ$7, MATCH(BI11,'💰 Revenue'!$C$5:$BJ$5,0)) -> 180
A15: Waiter/Waitress / Phục vụ bàn Salary | B15: =_xlfn.LET( _xlpm.prep_month, INDEX('⚙️ Other Assumptions'!$B$18:$AK$18,MATCH(B$10,'⚙️ Other Assumptions'!$B$14:$AK$14,0)), _xlpm.days_per_month, INDEX('💰 Revenue'!$C$8:$BJ$8,MATCH(B11,'💰 Revenue'!$C$5:$BJ5,0)), _xlpm.number_of_worker, B13, _xlpm.hourly_rate,$D$4, _xlpm.6hrs_pershift, 6 , _xlpm.waiter_sal, _xlpm.days_per_month * _xlpm.number_of_worker * _xlpm.hourly_rate * _xlpm.6hrs_pershift, IF(B$10> 10, _xlpm.waiter_sal, IF(_xlpm.prep_month > 0, _xlpm.waiter_sal,0))) -> 0 | C15: =_xlfn.LET( _xlpm.prep_month, INDEX('⚙️ Other Assumptions'!$B$18:$AK$18,MATCH(C$10,'⚙️ Other Assumptions'!$B$14:$AK$14,0)), _xlpm.days_per_month, INDEX('💰 Revenue'!$C$8:$BJ$8,MATCH(C11,'💰 Revenue'!$C$5:$BJ5,0)), _xlpm.number_of_worker, C13, _xlpm.hourly_rate,$D$4, _xlpm.6hrs_pershift, 6 , _xlpm.waiter_sal, _xlpm.days_per_month * _xlpm.number_of_worker * _xlpm.hourly_rate * _xlpm.6hrs_pershift, IF(C$10> 10, _xlpm.waiter_sal, IF(_xlpm.prep_month > 0, _xlpm.waiter_sal,0))) -> 0 | D15: =_xlfn.LET( _xlpm.prep_month, INDEX('⚙️ Other Assumptions'!$B$18:$AK$18,MATCH(D$10,'⚙️ Other Assumptions'!$B$14:$AK$14,0)), _xlpm.days_per_month, INDEX('💰 Revenue'!$C$8:$BJ$8,MATCH(D11,'💰 Revenue'!$C$5:$BJ5,0)), _xlpm.number_of_worker, D13, _xlpm.hourly_rate,$D$4, _xlpm.6hrs_pershift, 6 , _xlpm.waiter_sal, _xlpm.days_per_month * _xlpm.number_of_worker * _xlpm.hourly_rate * _xlpm.6hrs_pershift, IF(D$10> 10, _xlpm.waiter_sal, IF(_xlpm.prep_month > 0, _xlpm.waiter_sal,0))) -> 12276000 | E15: =_xlfn.LET( _xlpm.prep_month, INDEX('⚙️ Other Assumptions'!$B$18:$AK$18,MATCH(E$10,'⚙️ Other Assumptions'!$B$14:$AK$14,0)), _xlpm.days_per_month, INDEX('💰 Revenue'!$C$8:$BJ$8,MATCH(E11,'💰 Revenue'!$C$5:$BJ5,0)), _xlpm.number_of_worker, E13, _xlpm.hourly_rate,$D$4, _xlpm.6hrs_pershift, 6 , _xlpm.waiter_sal, _xlpm.days_per_month * _xlpm.number_of_worker * _xlpm.hourly_rate * _xlpm.6hrs_pershift, IF(E$10> 10, _xlpm.waiter_sal, IF(_xlpm.prep_month > 0, _xlpm.waiter_sal,0))) -> 12276000 | F15: =_xlfn.LET( _xlpm.prep_month, INDEX('⚙️ Other Assumptions'!$B$18:$AK$18,MATCH(F$10,'⚙️ Other Assumptions'!$B$14:$AK$14,0)), _xlpm.days_per_month, INDEX('💰 Revenue'!$C$8:$BJ$8,MATCH(F11,'💰 Revenue'!$C$5:$BJ5,0)), _xlpm.number_of_worker, F13, _xlpm.hourly_rate,$D$4, _xlpm.6hrs_pershift, 6 , _xlpm.waiter_sal, _xlpm.days_per_month * _xlpm.number_of_worker * _xlpm.hourly_rate * _xlpm.6hrs_pershift, IF(F$10> 10, _xlpm.waiter_sal, IF(_xlpm.prep_month > 0, _xlpm.waiter_sal,0))) -> 11484000 | G15: =_xlfn.LET( _xlpm.prep_month, INDEX('⚙️ Other Assumptions'!$B$18:$AK$18,MATCH(G$10,'⚙️ Other Assumptions'!$B$14:$AK$14,0)), _xlpm.days_per_month, INDEX('💰 Revenue'!$C$8:$BJ$8,MATCH(G11,'💰 Revenue'!$C$5:$BJ5,0)), _xlpm.number_of_worker, G13, _xlpm.hourly_rate,$D$4, _xlpm.6hrs_pershift, 6 , _xlpm.waiter_sal, _xlpm.days_per_month * _xlpm.number_of_worker * _xlpm.hourly_rate * _xlpm.6hrs_pershift, IF(G$10> 10, _xlpm.waiter_sal, IF(_xlpm.prep_month > 0, _xlpm.waiter_sal,0))) -> 12276000 | H15: =_xlfn.LET( _xlpm.prep_month, INDEX('⚙️ Other Assumptions'!$B$18:$AK$18,MATCH(H$10,'⚙️ Other Assumptions'!$B$14:$AK$14,0)), _xlpm.days_per_month, INDEX('💰 Revenue'!$C$8:$BJ$8,MATCH(H11,'💰 Revenue'!$C$5:$BJ5,0)), _xlpm.number_of_worker, H13, _xlpm.hourly_rate,$D$4, _xlpm.6hrs_pershift, 6 , _xlpm.waiter_sal, _xlpm.days_per_month * _xlpm.number_of_worker * _xlpm.hourly_rate * _xlpm.6hrs_pershift, IF(H$10> 10, _xlpm.waiter_sal, IF(_xlpm.prep_month > 0, _xlpm.waiter_sal,0))) -> 17820000 | I15: =_xlfn.LET( _xlpm.prep_month, INDEX('⚙️ Other Assumptions'!$B$18:$AK$18,MATCH(I$10,'⚙️ Other Assumptions'!$B$14:$AK$14,0)), _xlpm.days_per_month, INDEX('💰 Revenue'!$C$8:$BJ$8,MATCH(I11,'💰 Revenue'!$C$5:$BJ5,0)), _xlpm.number_of_worker, I13, _xlpm.hourly_rate,$D$4, _xlpm.6hrs_pershift, 6 , _xlpm.waiter_sal, _xlpm.days_per_month * _xlpm.number_of_worker * _xlpm.hourly_rate * _xlpm.6hrs_pershift, IF(I$10> 10, _xlpm.waiter_sal, IF(_xlpm.prep_month > 0, _xlpm.waiter_sal,0))) -> 18414000 | ... BI15: =_xlfn.LET( _xlpm.prep_month, INDEX('⚙️ Other Assumptions'!$B$18:$AK$18,MATCH(BI$10,'⚙️ Other Assumptions'!$B$14:$AK$14,0)), _xlpm.days_per_month, INDEX('💰 Revenue'!$C$8:$BJ$8,MATCH(BI11,'💰 Revenue'!$C$5:$BJ5,0)), _xlpm.number_of_worker, BI13, _xlpm.hourly_rate,$D$4, _xlpm.6hrs_pershift, 6 , _xlpm.waiter_sal, _xlpm.days_per_month * _xlpm.number_of_worker * _xlpm.hourly_rate * _xlpm.6hrs_pershift, IF(BI$10> 10, _xlpm.waiter_sal, IF(_xlpm.prep_month > 0, _xlpm.waiter_sal,0))) -> 23760000
